{
    DataVersion: 3955,
    size: [7, 7, 7],
    data: [
        {pos: [3, 0, 1], state: "ae2:quartz_block"},
        {pos: [2, 0, 2], state: "ufo:quantum_hyper_mechanical_casing"},
        {pos: [3, 0, 2], state: "ufo:quantum_hyper_mechanical_casing"},
        {pos: [4, 0, 2], state: "ufo:quantum_hyper_mechanical_casing"},
        {pos: [1, 0, 3], state: "ae2:fluix_block"},
        {pos: [2, 0, 3], state: "ufo:quantum_hyper_mechanical_casing"},
        {pos: [3, 0, 3], state: "ufo:quantum_hyper_mechanical_casing"},
        {pos: [4, 0, 3], state: "ufo:quantum_hyper_mechanical_casing"},
        {pos: [5, 0, 3], state: "ae2:fluix_block"},
        {pos: [2, 0, 4], state: "ufo:quantum_hyper_mechanical_casing"},
        {pos: [3, 0, 4], state: "ufo:quantum_hyper_mechanical_casing"},
        {pos: [4, 0, 4], state: "ufo:quantum_hyper_mechanical_casing"},
        {pos: [3, 0, 5], state: "ae2:quartz_block"},
        {pos: [3, 1, 0], state: "ae2:quartz_block"},
        {pos: [1, 1, 1], state: "ae2:quartz_vibrant_glass"},
        {pos: [2, 1, 1], state: "ae2:quartz_vibrant_glass"},
        {pos: [3, 1, 1], state: "ufo:graviton_plated_casing"},
        {pos: [4, 1, 1], state: "ae2:quartz_vibrant_glass"},
        {pos: [5, 1, 1], state: "ae2:quartz_vibrant_glass"},
        {pos: [1, 1, 2], state: "ae2:quartz_vibrant_glass"},
        {pos: [3, 1, 2], state: "ufo:stellar_field_generator_t1"},
        {pos: [5, 1, 2], state: "ae2:quartz_vibrant_glass"},
        {pos: [0, 1, 3], state: "ae2:fluix_block"},
        {pos: [1, 1, 3], state: "ufo:graviton_plated_casing"},
        {pos: [2, 1, 3], state: "ufo:stellar_field_generator_t1"},
        {pos: [3, 1, 3], state: "ufo:stellar_field_generator_t1"},
        {pos: [4, 1, 3], state: "ufo:stellar_field_generator_t1"},
        {pos: [5, 1, 3], state: "ufo:graviton_plated_casing"},
        {pos: [6, 1, 3], state: "ae2:fluix_block"},
        {pos: [1, 1, 4], state: "ae2:quartz_vibrant_glass"},
        {pos: [3, 1, 4], state: "ufo:stellar_field_generator_t1"},
        {pos: [5, 1, 4], state: "ae2:quartz_vibrant_glass"},
        {pos: [1, 1, 5], state: "ae2:quartz_vibrant_glass"},
        {pos: [2, 1, 5], state: "ae2:quartz_vibrant_glass"},
        {pos: [3, 1, 5], state: "ufo:graviton_plated_casing"},
        {pos: [4, 1, 5], state: "ae2:quartz_vibrant_glass"},
        {pos: [5, 1, 5], state: "ae2:quartz_vibrant_glass"},
        {pos: [3, 1, 6], state: "ae2:quartz_block"},
        {pos: [2, 2, 0], state: "ufo:quantum_hyper_mechanical_casing"},
        {pos: [3, 2, 0], state: "ufo:quantum_hyper_mechanical_casing"},
        {pos: [4, 2, 0], state: "ufo:quantum_hyper_mechanical_casing"},
        {pos: [1, 2, 1], state: "ae2:quartz_vibrant_glass"},
        {pos: [3, 2, 1], state: "ufo:stellar_field_generator_t1"},
        {pos: [5, 2, 1], state: "ae2:quartz_vibrant_glass"},
        {pos: [0, 2, 2], state: "ufo:quantum_hyper_mechanical_casing"},
        {pos: [6, 2, 2], state: "ufo:quantum_hyper_mechanical_casing"},
        {pos: [0, 2, 3], state: "ufo:quantum_hyper_mechanical_casing"},
        {pos: [1, 2, 3], state: "ufo:stellar_field_generator_t1"},
        {pos: [3, 2, 3], state: "ufo:stellar_field_generator_t1"},
        {pos: [5, 2, 3], state: "ufo:stellar_field_generator_t1"},
        {pos: [6, 2, 3], state: "ufo:quantum_hyper_mechanical_casing"},
        {pos: [0, 2, 4], state: "ufo:quantum_hyper_mechanical_casing"},
        {pos: [6, 2, 4], state: "ufo:quantum_hyper_mechanical_casing"},
        {pos: [1, 2, 5], state: "ae2:quartz_vibrant_glass"},
        {pos: [3, 2, 5], state: "ufo:stellar_field_generator_t1"},
        {pos: [5, 2, 5], state: "ae2:quartz_vibrant_glass"},
        {pos: [2, 2, 6], state: "ufo:quantum_hyper_mechanical_casing"},
        {pos: [3, 2, 6], state: "ufo:quantum_hyper_mechanical_casing"},
        {pos: [4, 2, 6], state: "ufo:quantum_hyper_mechanical_casing"},
        {pos: [1, 3, 0], state: "ae2:quartz_block"},
        {pos: [2, 3, 0], state: "ufo:quantum_hyper_mechanical_casing"},
        {pos: [3, 3, 0], state: "ufo:quantum_hyper_mechanical_casing"},
        {pos: [4, 3, 0], state: "ufo:quantum_hyper_mechanical_casing"},
        {pos: [5, 3, 0], state: "ae2:quartz_block"},
        {pos: [0, 3, 1], state: "ae2:fluix_block"},
        {pos: [1, 3, 1], state: "ae2:quartz_vibrant_glass"},
        {pos: [3, 3, 1], state: "ufo:stellar_field_generator_t1"},
        {pos: [5, 3, 1], state: "ae2:quartz_vibrant_glass"},
        {pos: [6, 3, 1], state: "ae2:fluix_block"},
        {pos: [0, 3, 2], state: "ufo:quantum_hyper_mechanical_casing"},
        {pos: [6, 3, 2], state: "ufo:quantum_hyper_mechanical_casing"},
        {pos: [0, 3, 3], state: "ufo:infinity_fabrication_singularity_controller"},
        {pos: [1, 3, 3], state: "ufo:stellar_field_generator_t1"},
        {pos: [3, 3, 3], state: "ufo:stellar_field_generator_t1"},
        {pos: [5, 3, 3], state: "ufo:stellar_field_generator_t1"},
        {pos: [6, 3, 3], state: "ufo:quantum_grid_link"},
        {pos: [0, 3, 4], state: "ufo:quantum_hyper_mechanical_casing"},
        {pos: [6, 3, 4], state: "ufo:quantum_hyper_mechanical_casing"},
        {pos: [0, 3, 5], state: "ae2:fluix_block"},
        {pos: [1, 3, 5], state: "ae2:quartz_vibrant_glass"},
        {pos: [3, 3, 5], state: "ufo:stellar_field_generator_t1"},
        {pos: [5, 3, 5], state: "ae2:quartz_vibrant_glass"},
        {pos: [6, 3, 5], state: "ae2:fluix_block"},
        {pos: [1, 3, 6], state: "ae2:quartz_block"},
        {pos: [2, 3, 6], state: "ufo:quantum_hyper_mechanical_casing"},
        {pos: [3, 3, 6], state: "ufo:quantum_hyper_mechanical_casing"},
        {pos: [4, 3, 6], state: "ufo:quantum_hyper_mechanical_casing"},
        {pos: [5, 3, 6], state: "ae2:quartz_block"},
        {pos: [2, 4, 0], state: "ufo:quantum_hyper_mechanical_casing"},
        {pos: [3, 4, 0], state: "ufo:quantum_hyper_mechanical_casing"},
        {pos: [4, 4, 0], state: "ufo:quantum_hyper_mechanical_casing"},
        {pos: [1, 4, 1], state: "ae2:quartz_vibrant_glass"},
        {pos: [3, 4, 1], state: "ufo:stellar_field_generator_t1"},
        {pos: [5, 4, 1], state: "ae2:quartz_vibrant_glass"},
        {pos: [0, 4, 2], state: "ufo:quantum_hyper_mechanical_casing"},
        {pos: [6, 4, 2], state: "ufo:quantum_hyper_mechanical_casing"},
        {pos: [0, 4, 3], state: "ufo:quantum_hyper_mechanical_casing"},
        {pos: [1, 4, 3], state: "ufo:stellar_field_generator_t1"},
        {pos: [3, 4, 3], state: "ufo:stellar_field_generator_t1"},
        {pos: [5, 4, 3], state: "ufo:stellar_field_generator_t1"},
        {pos: [6, 4, 3], state: "ufo:quantum_hyper_mechanical_casing"},
        {pos: [0, 4, 4], state: "ufo:quantum_hyper_mechanical_casing"},
        {pos: [6, 4, 4], state: "ufo:quantum_hyper_mechanical_casing"},
        {pos: [1, 4, 5], state: "ae2:quartz_vibrant_glass"},
        {pos: [3, 4, 5], state: "ufo:stellar_field_generator_t1"},
        {pos: [5, 4, 5], state: "ae2:quartz_vibrant_glass"},
        {pos: [2, 4, 6], state: "ufo:quantum_hyper_mechanical_casing"},
        {pos: [3, 4, 6], state: "ufo:quantum_hyper_mechanical_casing"},
        {pos: [4, 4, 6], state: "ufo:quantum_hyper_mechanical_casing"},
        {pos: [3, 5, 0], state: "ae2:quartz_block"},
        {pos: [1, 5, 1], state: "ae2:quartz_vibrant_glass"},
        {pos: [2, 5, 1], state: "ae2:quartz_vibrant_glass"},
        {pos: [3, 5, 1], state: "ufo:graviton_plated_casing"},
        {pos: [4, 5, 1], state: "ae2:quartz_vibrant_glass"},
        {pos: [5, 5, 1], state: "ae2:quartz_vibrant_glass"},
        {pos: [1, 5, 2], state: "ae2:quartz_vibrant_glass"},
        {pos: [3, 5, 2], state: "ufo:stellar_field_generator_t1"},
        {pos: [5, 5, 2], state: "ae2:quartz_vibrant_glass"},
        {pos: [0, 5, 3], state: "ae2:fluix_block"},
        {pos: [1, 5, 3], state: "ufo:graviton_plated_casing"},
        {pos: [2, 5, 3], state: "ufo:stellar_field_generator_t1"},
        {pos: [3, 5, 3], state: "ufo:stellar_field_generator_t1"},
        {pos: [4, 5, 3], state: "ufo:stellar_field_generator_t1"},
        {pos: [5, 5, 3], state: "ufo:graviton_plated_casing"},
        {pos: [6, 5, 3], state: "ae2:fluix_block"},
        {pos: [1, 5, 4], state: "ae2:quartz_vibrant_glass"},
        {pos: [3, 5, 4], state: "ufo:stellar_field_generator_t1"},
        {pos: [5, 5, 4], state: "ae2:quartz_vibrant_glass"},
        {pos: [1, 5, 5], state: "ae2:quartz_vibrant_glass"},
        {pos: [2, 5, 5], state: "ae2:quartz_vibrant_glass"},
        {pos: [3, 5, 5], state: "ufo:graviton_plated_casing"},
        {pos: [4, 5, 5], state: "ae2:quartz_vibrant_glass"},
        {pos: [5, 5, 5], state: "ae2:quartz_vibrant_glass"},
        {pos: [3, 5, 6], state: "ae2:quartz_block"},
        {pos: [3, 6, 1], state: "ae2:quartz_block"},
        {pos: [2, 6, 2], state: "ufo:quantum_hyper_mechanical_casing"},
        {pos: [3, 6, 2], state: "ufo:quantum_hyper_mechanical_casing"},
        {pos: [4, 6, 2], state: "ufo:quantum_hyper_mechanical_casing"},
        {pos: [1, 6, 3], state: "ae2:fluix_block"},
        {pos: [2, 6, 3], state: "ufo:quantum_hyper_mechanical_casing"},
        {pos: [3, 6, 3], state: "ufo:quantum_hyper_mechanical_casing"},
        {pos: [4, 6, 3], state: "ufo:quantum_hyper_mechanical_casing"},
        {pos: [5, 6, 3], state: "ae2:fluix_block"},
        {pos: [2, 6, 4], state: "ufo:quantum_hyper_mechanical_casing"},
        {pos: [3, 6, 4], state: "ufo:quantum_hyper_mechanical_casing"},
        {pos: [4, 6, 4], state: "ufo:quantum_hyper_mechanical_casing"},
        {pos: [3, 6, 5], state: "ae2:quartz_block"}
    ],
    entities: [],
    palette: [
        "ae2:quartz_block",
        "ufo:quantum_hyper_mechanical_casing",
        "ae2:fluix_block",
        "ae2:quartz_vibrant_glass",
        "ufo:graviton_plated_casing",
        "ufo:stellar_field_generator_t1",
        "ufo:infinity_fabrication_singularity_controller",
        "ufo:quantum_grid_link"
    ]
}
