{
    DataVersion: 3955,
    size: [5, 7, 12],
    data: [
        {pos: [0, 0, 1], state: "ae2:quartz_block"},
        {pos: [2, 0, 1], state: "ae2:fluix_block"},
        {pos: [4, 0, 1], state: "ae2:quartz_block"},
        {pos: [1, 0, 2], state: "ufo:quantum_hyper_mechanical_casing"},
        {pos: [2, 0, 2], state: "ufo:quantum_hyper_mechanical_casing"},
        {pos: [3, 0, 2], state: "ufo:quantum_hyper_mechanical_casing"},
        {pos: [1, 0, 3], state: "ufo:quantum_hyper_mechanical_casing"},
        {pos: [2, 0, 3], state: "ufo:quantum_hyper_mechanical_casing"},
        {pos: [3, 0, 3], state: "ufo:quantum_hyper_mechanical_casing"},
        {pos: [1, 0, 4], state: "ufo:quantum_hyper_mechanical_casing"},
        {pos: [2, 0, 4], state: "ufo:quantum_hyper_mechanical_casing"},
        {pos: [3, 0, 4], state: "ufo:quantum_hyper_mechanical_casing"},
        {pos: [0, 0, 5], state: "ae2:quartz_block"},
        {pos: [1, 0, 5], state: "ufo:quantum_hyper_mechanical_casing"},
        {pos: [2, 0, 5], state: "ufo:quantum_hyper_mechanical_casing"},
        {pos: [3, 0, 5], state: "ufo:quantum_hyper_mechanical_casing"},
        {pos: [4, 0, 5], state: "ae2:quartz_block"},
        {pos: [0, 0, 6], state: "ae2:quartz_block"},
        {pos: [1, 0, 6], state: "ufo:quantum_hyper_mechanical_casing"},
        {pos: [2, 0, 6], state: "ufo:quantum_hyper_mechanical_casing"},
        {pos: [3, 0, 6], state: "ufo:quantum_hyper_mechanical_casing"},
        {pos: [4, 0, 6], state: "ae2:quartz_block"},
        {pos: [1, 0, 7], state: "ufo:quantum_hyper_mechanical_casing"},
        {pos: [2, 0, 7], state: "ufo:quantum_hyper_mechanical_casing"},
        {pos: [3, 0, 7], state: "ufo:quantum_hyper_mechanical_casing"},
        {pos: [1, 0, 8], state: "ufo:quantum_hyper_mechanical_casing"},
        {pos: [2, 0, 8], state: "ufo:quantum_hyper_mechanical_casing"},
        {pos: [3, 0, 8], state: "ufo:quantum_hyper_mechanical_casing"},
        {pos: [1, 0, 9], state: "ufo:quantum_hyper_mechanical_casing"},
        {pos: [2, 0, 9], state: "ufo:quantum_hyper_mechanical_casing"},
        {pos: [3, 0, 9], state: "ufo:quantum_hyper_mechanical_casing"},
        {pos: [0, 0, 10], state: "ae2:quartz_block"},
        {pos: [2, 0, 10], state: "ae2:fluix_block"},
        {pos: [4, 0, 10], state: "ae2:quartz_block"},
        {pos: [2, 1, 0], state: "ae2:fluix_block"},
        {pos: [0, 1, 1], state: "ufo:quantum_hyper_mechanical_casing"},
        {pos: [1, 1, 1], state: "ufo:quantum_hyper_mechanical_casing"},
        {pos: [2, 1, 1], state: "ufo:stellar_field_generator_t1"},
        {pos: [3, 1, 1], state: "ufo:quantum_hyper_mechanical_casing"},
        {pos: [4, 1, 1], state: "ufo:quantum_hyper_mechanical_casing"},
        {pos: [0, 1, 2], state: "ufo:quantum_hyper_mechanical_casing"},
        {pos: [1, 1, 2], state: "ae2:quartz_vibrant_glass"},
        {pos: [2, 1, 2], state: "ufo:stellar_field_generator_t1"},
        {pos: [3, 1, 2], state: "ufo:stellar_field_generator_t1"},
        {pos: [4, 1, 2], state: "ufo:quantum_hyper_mechanical_casing"},
        {pos: [0, 1, 3], state: "ufo:stellar_field_generator_t1"},
        {pos: [1, 1, 3], state: "ae2:quartz_vibrant_glass"},
        {pos: [2, 1, 3], state: "ae2:quartz_vibrant_glass"},
        {pos: [3, 1, 3], state: "ufo:stellar_field_generator_t1"},
        {pos: [4, 1, 3], state: "ufo:stellar_field_generator_t1"},
        {pos: [0, 1, 4], state: "ufo:stellar_field_generator_t1"},
        {pos: [1, 1, 4], state: "ufo:stellar_field_generator_t1"},
        {pos: [2, 1, 4], state: "ae2:quartz_vibrant_glass"},
        {pos: [3, 1, 4], state: "ae2:quartz_vibrant_glass"},
        {pos: [4, 1, 4], state: "ufo:stellar_field_generator_t1"},
        {pos: [0, 1, 5], state: "ae2:quartz_vibrant_glass"},
        {pos: [1, 1, 5], state: "ufo:stellar_field_generator_t1"},
        {pos: [2, 1, 5], state: "ufo:stellar_field_generator_t1"},
        {pos: [3, 1, 5], state: "ae2:quartz_vibrant_glass"},
        {pos: [4, 1, 5], state: "ae2:quartz_vibrant_glass"},
        {pos: [0, 1, 6], state: "ae2:quartz_vibrant_glass"},
        {pos: [1, 1, 6], state: "ae2:quartz_vibrant_glass"},
        {pos: [2, 1, 6], state: "ufo:stellar_field_generator_t1"},
        {pos: [3, 1, 6], state: "ufo:stellar_field_generator_t1"},
        {pos: [4, 1, 6], state: "ae2:quartz_vibrant_glass"},
        {pos: [0, 1, 7], state: "ufo:stellar_field_generator_t1"},
        {pos: [1, 1, 7], state: "ae2:quartz_vibrant_glass"},
        {pos: [2, 1, 7], state: "ae2:quartz_vibrant_glass"},
        {pos: [3, 1, 7], state: "ufo:stellar_field_generator_t1"},
        {pos: [4, 1, 7], state: "ufo:stellar_field_generator_t1"},
        {pos: [0, 1, 8], state: "ufo:stellar_field_generator_t1"},
        {pos: [1, 1, 8], state: "ufo:stellar_field_generator_t1"},
        {pos: [2, 1, 8], state: "ae2:quartz_vibrant_glass"},
        {pos: [3, 1, 8], state: "ae2:quartz_vibrant_glass"},
        {pos: [4, 1, 8], state: "ufo:stellar_field_generator_t1"},
        {pos: [0, 1, 9], state: "ufo:quantum_hyper_mechanical_casing"},
        {pos: [1, 1, 9], state: "ufo:stellar_field_generator_t1"},
        {pos: [2, 1, 9], state: "ufo:stellar_field_generator_t1"},
        {pos: [3, 1, 9], state: "ae2:quartz_vibrant_glass"},
        {pos: [4, 1, 9], state: "ufo:quantum_hyper_mechanical_casing"},
        {pos: [0, 1, 10], state: "ufo:quantum_hyper_mechanical_casing"},
        {pos: [1, 1, 10], state: "ufo:quantum_hyper_mechanical_casing"},
        {pos: [2, 1, 10], state: "ufo:stellar_field_generator_t1"},
        {pos: [3, 1, 10], state: "ufo:quantum_hyper_mechanical_casing"},
        {pos: [4, 1, 10], state: "ufo:quantum_hyper_mechanical_casing"},
        {pos: [2, 1, 11], state: "ae2:fluix_block"},
        {pos: [1, 2, 0], state: "ae2:quartz_vibrant_glass"},
        {pos: [2, 2, 0], state: "ae2:quartz_vibrant_glass"},
        {pos: [3, 2, 0], state: "ae2:quartz_vibrant_glass"},
        {pos: [0, 2, 1], state: "ufo:quantum_hyper_mechanical_casing"},
        {pos: [4, 2, 1], state: "ufo:quantum_hyper_mechanical_casing"},
        {pos: [0, 2, 2], state: "ufo:stellar_field_generator_t1"},
        {pos: [4, 2, 2], state: "ufo:stellar_field_generator_t1"},
        {pos: [0, 2, 3], state: "ufo:stellar_field_generator_t1"},
        {pos: [4, 2, 3], state: "ufo:stellar_field_generator_t1"},
        {pos: [0, 2, 4], state: "ae2:quartz_vibrant_glass"},
        {pos: [4, 2, 4], state: "ae2:quartz_vibrant_glass"},
        {pos: [0, 2, 5], state: "ae2:quartz_vibrant_glass"},
        {pos: [4, 2, 5], state: "ae2:quartz_vibrant_glass"},
        {pos: [0, 2, 6], state: "ufo:stellar_field_generator_t1"},
        {pos: [4, 2, 6], state: "ufo:stellar_field_generator_t1"},
        {pos: [0, 2, 7], state: "ufo:stellar_field_generator_t1"},
        {pos: [4, 2, 7], state: "ufo:stellar_field_generator_t1"},
        {pos: [0, 2, 8], state: "ae2:quartz_vibrant_glass"},
        {pos: [4, 2, 8], state: "ae2:quartz_vibrant_glass"},
        {pos: [0, 2, 9], state: "ae2:quartz_vibrant_glass"},
        {pos: [4, 2, 9], state: "ae2:quartz_vibrant_glass"},
        {pos: [0, 2, 10], state: "ufo:quantum_hyper_mechanical_casing"},
        {pos: [4, 2, 10], state: "ufo:quantum_hyper_mechanical_casing"},
        {pos: [1, 2, 11], state: "ae2:quartz_vibrant_glass"},
        {pos: [2, 2, 11], state: "ae2:quartz_vibrant_glass"},
        {pos: [3, 2, 11], state: "ae2:quartz_vibrant_glass"},
        {pos: [0, 3, 0], state: "ae2:fluix_block"},
        {pos: [1, 3, 0], state: "ae2:quartz_vibrant_glass"},
        {pos: [2, 3, 0], state: "ufo:quantum_processor_assembler_controller"},
        {pos: [3, 3, 0], state: "ae2:quartz_vibrant_glass"},
        {pos: [4, 3, 0], state: "ae2:fluix_block"},
        {pos: [0, 3, 1], state: "ufo:stellar_field_generator_t1"},
        {pos: [4, 3, 1], state: "ufo:stellar_field_generator_t1"},
        {pos: [0, 3, 2], state: "ufo:stellar_field_generator_t1"},
        {pos: [4, 3, 2], state: "ufo:stellar_field_generator_t1"},
        {pos: [0, 3, 3], state: "ae2:quartz_vibrant_glass"},
        {pos: [4, 3, 3], state: "ae2:quartz_vibrant_glass"},
        {pos: [0, 3, 4], state: "ae2:quartz_vibrant_glass"},
        {pos: [4, 3, 4], state: "ae2:quartz_vibrant_glass"},
        {pos: [0, 3, 5], state: "ufo:stellar_field_generator_t1"},
        {pos: [4, 3, 5], state: "ufo:stellar_field_generator_t1"},
        {pos: [0, 3, 6], state: "ufo:stellar_field_generator_t1"},
        {pos: [4, 3, 6], state: "ufo:stellar_field_generator_t1"},
        {pos: [0, 3, 7], state: "ae2:quartz_vibrant_glass"},
        {pos: [4, 3, 7], state: "ae2:quartz_vibrant_glass"},
        {pos: [0, 3, 8], state: "ae2:quartz_vibrant_glass"},
        {pos: [4, 3, 8], state: "ae2:quartz_vibrant_glass"},
        {pos: [0, 3, 9], state: "ufo:stellar_field_generator_t1"},
        {pos: [4, 3, 9], state: "ufo:stellar_field_generator_t1"},
        {pos: [0, 3, 10], state: "ufo:stellar_field_generator_t1"},
        {pos: [4, 3, 10], state: "ufo:stellar_field_generator_t1"},
        {pos: [0, 3, 11], state: "ae2:fluix_block"},
        {pos: [1, 3, 11], state: "ae2:quartz_vibrant_glass"},
        {pos: [2, 3, 11], state: "ae2:quartz_vibrant_glass"},
        {pos: [3, 3, 11], state: "ae2:quartz_vibrant_glass"},
        {pos: [4, 3, 11], state: "ae2:fluix_block"},
        {pos: [1, 4, 0], state: "ae2:quartz_vibrant_glass"},
        {pos: [2, 4, 0], state: "ae2:quartz_vibrant_glass"},
        {pos: [3, 4, 0], state: "ae2:quartz_vibrant_glass"},
        {pos: [0, 4, 1], state: "ufo:quantum_hyper_mechanical_casing"},
        {pos: [4, 4, 1], state: "ufo:quantum_hyper_mechanical_casing"},
        {pos: [0, 4, 2], state: "ae2:quartz_vibrant_glass"},
        {pos: [4, 4, 2], state: "ae2:quartz_vibrant_glass"},
        {pos: [0, 4, 3], state: "ae2:quartz_vibrant_glass"},
        {pos: [4, 4, 3], state: "ae2:quartz_vibrant_glass"},
        {pos: [0, 4, 4], state: "ufo:stellar_field_generator_t1"},
        {pos: [4, 4, 4], state: "ufo:stellar_field_generator_t1"},
        {pos: [0, 4, 5], state: "ufo:stellar_field_generator_t1"},
        {pos: [4, 4, 5], state: "ufo:stellar_field_generator_t1"},
        {pos: [0, 4, 6], state: "ae2:quartz_vibrant_glass"},
        {pos: [4, 4, 6], state: "ae2:quartz_vibrant_glass"},
        {pos: [0, 4, 7], state: "ae2:quartz_vibrant_glass"},
        {pos: [4, 4, 7], state: "ae2:quartz_vibrant_glass"},
        {pos: [0, 4, 8], state: "ufo:stellar_field_generator_t1"},
        {pos: [4, 4, 8], state: "ufo:stellar_field_generator_t1"},
        {pos: [0, 4, 9], state: "ufo:stellar_field_generator_t1"},
        {pos: [4, 4, 9], state: "ufo:stellar_field_generator_t1"},
        {pos: [0, 4, 10], state: "ufo:quantum_hyper_mechanical_casing"},
        {pos: [4, 4, 10], state: "ufo:quantum_hyper_mechanical_casing"},
        {pos: [1, 4, 11], state: "ae2:quartz_vibrant_glass"},
        {pos: [2, 4, 11], state: "ae2:quartz_vibrant_glass"},
        {pos: [3, 4, 11], state: "ae2:quartz_vibrant_glass"},
        {pos: [2, 5, 0], state: "ae2:fluix_block"},
        {pos: [0, 5, 1], state: "ufo:quantum_hyper_mechanical_casing"},
        {pos: [1, 5, 1], state: "ufo:quantum_hyper_mechanical_casing"},
        {pos: [2, 5, 1], state: "ufo:stellar_field_generator_t1"},
        {pos: [3, 5, 1], state: "ufo:quantum_hyper_mechanical_casing"},
        {pos: [4, 5, 1], state: "ufo:quantum_hyper_mechanical_casing"},
        {pos: [0, 5, 2], state: "ufo:quantum_hyper_mechanical_casing"},
        {pos: [1, 5, 2], state: "ae2:quartz_vibrant_glass"},
        {pos: [2, 5, 2], state: "ufo:stellar_field_generator_t1"},
        {pos: [3, 5, 2], state: "ufo:stellar_field_generator_t1"},
        {pos: [4, 5, 2], state: "ufo:quantum_hyper_mechanical_casing"},
        {pos: [0, 5, 3], state: "ufo:stellar_field_generator_t1"},
        {pos: [1, 5, 3], state: "ae2:quartz_vibrant_glass"},
        {pos: [2, 5, 3], state: "ae2:quartz_vibrant_glass"},
        {pos: [3, 5, 3], state: "ufo:stellar_field_generator_t1"},
        {pos: [4, 5, 3], state: "ufo:stellar_field_generator_t1"},
        {pos: [0, 5, 4], state: "ufo:stellar_field_generator_t1"},
        {pos: [1, 5, 4], state: "ufo:stellar_field_generator_t1"},
        {pos: [2, 5, 4], state: "ae2:quartz_vibrant_glass"},
        {pos: [3, 5, 4], state: "ae2:quartz_vibrant_glass"},
        {pos: [4, 5, 4], state: "ufo:stellar_field_generator_t1"},
        {pos: [0, 5, 5], state: "ae2:quartz_vibrant_glass"},
        {pos: [1, 5, 5], state: "ufo:stellar_field_generator_t1"},
        {pos: [2, 5, 5], state: "ufo:stellar_field_generator_t1"},
        {pos: [3, 5, 5], state: "ae2:quartz_vibrant_glass"},
        {pos: [4, 5, 5], state: "ae2:quartz_vibrant_glass"},
        {pos: [0, 5, 6], state: "ae2:quartz_vibrant_glass"},
        {pos: [1, 5, 6], state: "ae2:quartz_vibrant_glass"},
        {pos: [2, 5, 6], state: "ufo:stellar_field_generator_t1"},
        {pos: [3, 5, 6], state: "ufo:stellar_field_generator_t1"},
        {pos: [4, 5, 6], state: "ae2:quartz_vibrant_glass"},
        {pos: [0, 5, 7], state: "ufo:stellar_field_generator_t1"},
        {pos: [1, 5, 7], state: "ae2:quartz_vibrant_glass"},
        {pos: [2, 5, 7], state: "ae2:quartz_vibrant_glass"},
        {pos: [3, 5, 7], state: "ufo:stellar_field_generator_t1"},
        {pos: [4, 5, 7], state: "ufo:stellar_field_generator_t1"},
        {pos: [0, 5, 8], state: "ufo:stellar_field_generator_t1"},
        {pos: [1, 5, 8], state: "ufo:stellar_field_generator_t1"},
        {pos: [2, 5, 8], state: "ae2:quartz_vibrant_glass"},
        {pos: [3, 5, 8], state: "ae2:quartz_vibrant_glass"},
        {pos: [4, 5, 8], state: "ufo:stellar_field_generator_t1"},
        {pos: [0, 5, 9], state: "ufo:quantum_hyper_mechanical_casing"},
        {pos: [1, 5, 9], state: "ufo:stellar_field_generator_t1"},
        {pos: [2, 5, 9], state: "ufo:stellar_field_generator_t1"},
        {pos: [3, 5, 9], state: "ae2:quartz_vibrant_glass"},
        {pos: [4, 5, 9], state: "ufo:quantum_hyper_mechanical_casing"},
        {pos: [0, 5, 10], state: "ufo:quantum_hyper_mechanical_casing"},
        {pos: [1, 5, 10], state: "ufo:quantum_hyper_mechanical_casing"},
        {pos: [2, 5, 10], state: "ufo:stellar_field_generator_t1"},
        {pos: [3, 5, 10], state: "ufo:quantum_hyper_mechanical_casing"},
        {pos: [4, 5, 10], state: "ufo:quantum_hyper_mechanical_casing"},
        {pos: [2, 5, 11], state: "ae2:fluix_block"},
        {pos: [0, 6, 1], state: "ae2:quartz_block"},
        {pos: [2, 6, 1], state: "ae2:fluix_block"},
        {pos: [4, 6, 1], state: "ae2:quartz_block"},
        {pos: [1, 6, 2], state: "ufo:quantum_hyper_mechanical_casing"},
        {pos: [2, 6, 2], state: "ufo:quantum_hyper_mechanical_casing"},
        {pos: [3, 6, 2], state: "ufo:quantum_hyper_mechanical_casing"},
        {pos: [1, 6, 3], state: "ufo:quantum_hyper_mechanical_casing"},
        {pos: [2, 6, 3], state: "ufo:quantum_hyper_mechanical_casing"},
        {pos: [3, 6, 3], state: "ufo:quantum_hyper_mechanical_casing"},
        {pos: [1, 6, 4], state: "ufo:quantum_hyper_mechanical_casing"},
        {pos: [2, 6, 4], state: "ufo:quantum_hyper_mechanical_casing"},
        {pos: [3, 6, 4], state: "ufo:quantum_hyper_mechanical_casing"},
        {pos: [0, 6, 5], state: "ae2:quartz_block"},
        {pos: [1, 6, 5], state: "ufo:quantum_hyper_mechanical_casing"},
        {pos: [2, 6, 5], state: "ufo:quantum_hyper_mechanical_casing"},
        {pos: [3, 6, 5], state: "ufo:quantum_hyper_mechanical_casing"},
        {pos: [4, 6, 5], state: "ae2:quartz_block"},
        {pos: [0, 6, 6], state: "ae2:quartz_block"},
        {pos: [1, 6, 6], state: "ufo:quantum_hyper_mechanical_casing"},
        {pos: [2, 6, 6], state: "ufo:quantum_hyper_mechanical_casing"},
        {pos: [3, 6, 6], state: "ufo:quantum_hyper_mechanical_casing"},
        {pos: [4, 6, 6], state: "ae2:quartz_block"},
        {pos: [1, 6, 7], state: "ufo:quantum_hyper_mechanical_casing"},
        {pos: [2, 6, 7], state: "ufo:quantum_hyper_mechanical_casing"},
        {pos: [3, 6, 7], state: "ufo:quantum_hyper_mechanical_casing"},
        {pos: [1, 6, 8], state: "ufo:quantum_hyper_mechanical_casing"},
        {pos: [2, 6, 8], state: "ufo:quantum_hyper_mechanical_casing"},
        {pos: [3, 6, 8], state: "ufo:quantum_hyper_mechanical_casing"},
        {pos: [1, 6, 9], state: "ufo:quantum_hyper_mechanical_casing"},
        {pos: [2, 6, 9], state: "ufo:quantum_hyper_mechanical_casing"},
        {pos: [3, 6, 9], state: "ufo:quantum_hyper_mechanical_casing"},
        {pos: [0, 6, 10], state: "ae2:quartz_block"},
        {pos: [2, 6, 10], state: "ae2:fluix_block"},
        {pos: [4, 6, 10], state: "ae2:quartz_block"}
    ],
    entities: [],
    palette: [
        "ae2:quartz_block",
        "ae2:fluix_block",
        "ufo:quantum_hyper_mechanical_casing",
        "ufo:stellar_field_generator_t1",
        "ae2:quartz_vibrant_glass",
        "ufo:quantum_processor_assembler_controller"
    ]
}
