{
    DataVersion: 3955,
    size: [7, 5, 9],
    data: [
        {pos: [0, 0, 0], state: "ufo:quantum_hyper_mechanical_casing"},
        {pos: [1, 0, 0], state: "ufo:quantum_hyper_mechanical_casing"},
        {pos: [2, 0, 0], state: "ufo:quantum_hyper_mechanical_casing"},
        {pos: [3, 0, 0], state: "ufo:quantum_hyper_mechanical_casing"},
        {pos: [4, 0, 0], state: "ufo:quantum_hyper_mechanical_casing"},
        {pos: [5, 0, 0], state: "ufo:quantum_hyper_mechanical_casing"},
        {pos: [6, 0, 0], state: "ufo:quantum_hyper_mechanical_casing"},
        {pos: [0, 0, 1], state: "ufo:quantum_hyper_mechanical_casing"},
        {pos: [1, 0, 1], state: "ufo:quantum_hyper_mechanical_casing"},
        {pos: [2, 0, 1], state: "ufo:quantum_hyper_mechanical_casing"},
        {pos: [3, 0, 1], state: "ufo:quantum_hyper_mechanical_casing"},
        {pos: [4, 0, 1], state: "ufo:quantum_hyper_mechanical_casing"},
        {pos: [5, 0, 1], state: "ufo:quantum_hyper_mechanical_casing"},
        {pos: [6, 0, 1], state: "ufo:quantum_hyper_mechanical_casing"},
        {pos: [0, 0, 2], state: "ufo:quantum_hyper_mechanical_casing"},
        {pos: [1, 0, 2], state: "ufo:quantum_hyper_mechanical_casing"},
        {pos: [2, 0, 2], state: "ufo:quantum_hyper_mechanical_casing"},
        {pos: [3, 0, 2], state: "ufo:quantum_hyper_mechanical_casing"},
        {pos: [4, 0, 2], state: "ufo:quantum_hyper_mechanical_casing"},
        {pos: [5, 0, 2], state: "ufo:quantum_hyper_mechanical_casing"},
        {pos: [6, 0, 2], state: "ufo:quantum_hyper_mechanical_casing"},
        {pos: [0, 0, 3], state: "ufo:quantum_hyper_mechanical_casing"},
        {pos: [1, 0, 3], state: "ufo:quantum_hyper_mechanical_casing"},
        {pos: [2, 0, 3], state: "ufo:quantum_hyper_mechanical_casing"},
        {pos: [3, 0, 3], state: "ufo:quantum_hyper_mechanical_casing"},
        {pos: [4, 0, 3], state: "ufo:quantum_hyper_mechanical_casing"},
        {pos: [5, 0, 3], state: "ufo:quantum_hyper_mechanical_casing"},
        {pos: [6, 0, 3], state: "ufo:quantum_hyper_mechanical_casing"},
        {pos: [1, 0, 4], state: "ufo:quantum_hyper_mechanical_casing"},
        {pos: [2, 0, 4], state: "ufo:quantum_hyper_mechanical_casing"},
        {pos: [3, 0, 4], state: "ufo:quantum_hyper_mechanical_casing"},
        {pos: [4, 0, 4], state: "ufo:quantum_hyper_mechanical_casing"},
        {pos: [5, 0, 4], state: "ufo:quantum_hyper_mechanical_casing"},
        {pos: [1, 0, 5], state: "ufo:quantum_hyper_mechanical_casing"},
        {pos: [2, 0, 5], state: "ae2:fluix_block"},
        {pos: [3, 0, 5], state: "ae2:fluix_block"},
        {pos: [4, 0, 5], state: "ae2:fluix_block"},
        {pos: [5, 0, 5], state: "ufo:quantum_hyper_mechanical_casing"},
        {pos: [1, 0, 6], state: "ufo:quantum_pattern_fabrication_matrix_controller"},
        {pos: [2, 0, 6], state: "ae2:fluix_block"},
        {pos: [3, 0, 6], state: "ae2:fluix_block"},
        {pos: [4, 0, 6], state: "ae2:fluix_block"},
        {pos: [5, 0, 6], state: "ufo:quantum_grid_link"},
        {pos: [1, 0, 7], state: "ufo:quantum_hyper_mechanical_casing"},
        {pos: [2, 0, 7], state: "ae2:fluix_block"},
        {pos: [3, 0, 7], state: "ae2:fluix_block"},
        {pos: [4, 0, 7], state: "ae2:fluix_block"},
        {pos: [5, 0, 7], state: "ufo:quantum_hyper_mechanical_casing"},
        {pos: [1, 0, 8], state: "ufo:quantum_hyper_mechanical_casing"},
        {pos: [2, 0, 8], state: "ufo:quantum_hyper_mechanical_casing"},
        {pos: [3, 0, 8], state: "ufo:quantum_hyper_mechanical_casing"},
        {pos: [4, 0, 8], state: "ufo:quantum_hyper_mechanical_casing"},
        {pos: [5, 0, 8], state: "ufo:quantum_hyper_mechanical_casing"},
        {pos: [0, 1, 0], state: "ufo:quantum_hyper_mechanical_casing"},
        {pos: [1, 1, 0], state: "ufo:quantum_hyper_mechanical_casing"},
        {pos: [2, 1, 0], state: "ae2:quartz_vibrant_glass"},
        {pos: [3, 1, 0], state: "ufo:quantum_hyper_mechanical_casing"},
        {pos: [4, 1, 0], state: "ae2:quartz_vibrant_glass"},
        {pos: [5, 1, 0], state: "ufo:quantum_hyper_mechanical_casing"},
        {pos: [6, 1, 0], state: "ufo:quantum_hyper_mechanical_casing"},
        {pos: [0, 1, 1], state: "ufo:quantum_hyper_mechanical_casing"},
        {pos: [1, 1, 1], state: "ufo:quantum_hyper_mechanical_casing"},
        {pos: [2, 1, 1], state: "ufo:stellar_field_generator_t1"},
        {pos: [3, 1, 1], state: "ufo:quantum_hyper_mechanical_casing"},
        {pos: [4, 1, 1], state: "ufo:stellar_field_generator_t1"},
        {pos: [5, 1, 1], state: "ufo:quantum_hyper_mechanical_casing"},
        {pos: [6, 1, 1], state: "ufo:quantum_hyper_mechanical_casing"},
        {pos: [0, 1, 2], state: "ufo:quantum_hyper_mechanical_casing"},
        {pos: [1, 1, 2], state: "ufo:quantum_hyper_mechanical_casing"},
        {pos: [2, 1, 2], state: "ufo:stellar_field_generator_t1"},
        {pos: [3, 1, 2], state: "ufo:quantum_hyper_mechanical_casing"},
        {pos: [4, 1, 2], state: "ufo:stellar_field_generator_t1"},
        {pos: [5, 1, 2], state: "ufo:quantum_hyper_mechanical_casing"},
        {pos: [6, 1, 2], state: "ufo:quantum_hyper_mechanical_casing"},
        {pos: [0, 1, 3], state: "ufo:quantum_hyper_mechanical_casing"},
        {pos: [1, 1, 3], state: "ufo:stellar_field_generator_t1"},
        {pos: [2, 1, 3], state: "ufo:stellar_field_generator_t1"},
        {pos: [3, 1, 3], state: "ufo:stellar_field_generator_t1"},
        {pos: [4, 1, 3], state: "ufo:stellar_field_generator_t1"},
        {pos: [5, 1, 3], state: "ufo:stellar_field_generator_t1"},
        {pos: [6, 1, 3], state: "ufo:quantum_hyper_mechanical_casing"},
        {pos: [1, 1, 4], state: "ufo:quantum_hyper_mechanical_casing"},
        {pos: [2, 1, 4], state: "ae2:quartz_block"},
        {pos: [3, 1, 4], state: "ufo:stellar_field_generator_t1"},
        {pos: [4, 1, 4], state: "ae2:quartz_block"},
        {pos: [5, 1, 4], state: "ufo:quantum_hyper_mechanical_casing"},
        {pos: [1, 1, 5], state: "ae2:quartz_vibrant_glass"},
        {pos: [3, 1, 5], state: "ufo:stellar_field_generator_t1"},
        {pos: [5, 1, 5], state: "ae2:quartz_vibrant_glass"},
        {pos: [1, 1, 6], state: "ae2:quartz_vibrant_glass"},
        {pos: [3, 1, 6], state: "ufo:stellar_field_generator_t1"},
        {pos: [5, 1, 6], state: "ae2:quartz_vibrant_glass"},
        {pos: [1, 1, 7], state: "ae2:quartz_vibrant_glass"},
        {pos: [5, 1, 7], state: "ae2:quartz_vibrant_glass"},
        {pos: [1, 1, 8], state: "ufo:quantum_hyper_mechanical_casing"},
        {pos: [2, 1, 8], state: "ae2:fluix_block"},
        {pos: [3, 1, 8], state: "ae2:quartz_vibrant_glass"},
        {pos: [4, 1, 8], state: "ae2:fluix_block"},
        {pos: [5, 1, 8], state: "ufo:quantum_hyper_mechanical_casing"},
        {pos: [0, 2, 0], state: "ae2:quartz_vibrant_glass"},
        {pos: [1, 2, 0], state: "ae2:quartz_vibrant_glass"},
        {pos: [2, 2, 0], state: "ae2:quartz_vibrant_glass"},
        {pos: [3, 2, 0], state: "ae2:quartz_vibrant_glass"},
        {pos: [4, 2, 0], state: "ae2:quartz_vibrant_glass"},
        {pos: [5, 2, 0], state: "ae2:quartz_vibrant_glass"},
        {pos: [6, 2, 0], state: "ae2:quartz_vibrant_glass"},
        {pos: [0, 2, 1], state: "ae2:quartz_vibrant_glass"},
        {pos: [6, 2, 1], state: "ae2:quartz_vibrant_glass"},
        {pos: [0, 2, 2], state: "ae2:quartz_vibrant_glass"},
        {pos: [6, 2, 2], state: "ae2:quartz_vibrant_glass"},
        {pos: [0, 2, 3], state: "ufo:quantum_hyper_mechanical_casing"},
        {pos: [1, 2, 3], state: "ufo:quantum_hyper_mechanical_casing"},
        {pos: [2, 2, 3], state: "ufo:stellar_field_generator_t1"},
        {pos: [3, 2, 3], state: "ufo:stellar_field_generator_t1"},
        {pos: [4, 2, 3], state: "ufo:stellar_field_generator_t1"},
        {pos: [5, 2, 3], state: "ufo:quantum_hyper_mechanical_casing"},
        {pos: [6, 2, 3], state: "ufo:quantum_hyper_mechanical_casing"},
        {pos: [1, 2, 4], state: "ufo:quantum_hyper_mechanical_casing"},
        {pos: [2, 2, 4], state: "ae2:quartz_block"},
        {pos: [3, 2, 4], state: "ae2:quartz_block"},
        {pos: [4, 2, 4], state: "ae2:quartz_block"},
        {pos: [5, 2, 4], state: "ufo:quantum_hyper_mechanical_casing"},
        {pos: [1, 2, 5], state: "ae2:quartz_vibrant_glass"},
        {pos: [5, 2, 5], state: "ae2:quartz_vibrant_glass"},
        {pos: [1, 2, 6], state: "ae2:quartz_vibrant_glass"},
        {pos: [3, 2, 6], state: "ufo:stellar_field_generator_t1"},
        {pos: [5, 2, 6], state: "ae2:quartz_vibrant_glass"},
        {pos: [1, 2, 7], state: "ae2:quartz_vibrant_glass"},
        {pos: [5, 2, 7], state: "ae2:quartz_vibrant_glass"},
        {pos: [1, 2, 8], state: "ufo:quantum_hyper_mechanical_casing"},
        {pos: [2, 2, 8], state: "ae2:fluix_block"},
        {pos: [3, 2, 8], state: "ae2:quartz_vibrant_glass"},
        {pos: [4, 2, 8], state: "ae2:fluix_block"},
        {pos: [5, 2, 8], state: "ufo:quantum_hyper_mechanical_casing"},
        {pos: [0, 3, 0], state: "ufo:quantum_hyper_mechanical_casing"},
        {pos: [1, 3, 0], state: "ufo:quantum_hyper_mechanical_casing"},
        {pos: [2, 3, 0], state: "ae2:quartz_vibrant_glass"},
        {pos: [3, 3, 0], state: "ufo:quantum_hyper_mechanical_casing"},
        {pos: [4, 3, 0], state: "ae2:quartz_vibrant_glass"},
        {pos: [5, 3, 0], state: "ufo:quantum_hyper_mechanical_casing"},
        {pos: [6, 3, 0], state: "ufo:quantum_hyper_mechanical_casing"},
        {pos: [0, 3, 1], state: "ufo:quantum_hyper_mechanical_casing"},
        {pos: [1, 3, 1], state: "ufo:quantum_hyper_mechanical_casing"},
        {pos: [3, 3, 1], state: "ufo:quantum_hyper_mechanical_casing"},
        {pos: [5, 3, 1], state: "ufo:quantum_hyper_mechanical_casing"},
        {pos: [6, 3, 1], state: "ufo:quantum_hyper_mechanical_casing"},
        {pos: [0, 3, 2], state: "ae2:quartz_vibrant_glass"},
        {pos: [6, 3, 2], state: "ae2:quartz_vibrant_glass"},
        {pos: [0, 3, 3], state: "ufo:quantum_hyper_mechanical_casing"},
        {pos: [1, 3, 3], state: "ufo:quantum_hyper_mechanical_casing"},
        {pos: [2, 3, 3], state: "ufo:stellar_field_generator_t1"},
        {pos: [3, 3, 3], state: "ufo:stellar_field_generator_t1"},
        {pos: [4, 3, 3], state: "ufo:stellar_field_generator_t1"},
        {pos: [5, 3, 3], state: "ufo:quantum_hyper_mechanical_casing"},
        {pos: [6, 3, 3], state: "ufo:quantum_hyper_mechanical_casing"},
        {pos: [1, 3, 4], state: "ufo:quantum_hyper_mechanical_casing"},
        {pos: [2, 3, 4], state: "ae2:quartz_block"},
        {pos: [3, 3, 4], state: "ufo:stellar_field_generator_t1"},
        {pos: [4, 3, 4], state: "ae2:quartz_block"},
        {pos: [5, 3, 4], state: "ufo:quantum_hyper_mechanical_casing"},
        {pos: [1, 3, 5], state: "ae2:quartz_vibrant_glass"},
        {pos: [3, 3, 5], state: "ufo:stellar_field_generator_t1"},
        {pos: [5, 3, 5], state: "ae2:quartz_vibrant_glass"},
        {pos: [1, 3, 6], state: "ae2:quartz_vibrant_glass"},
        {pos: [3, 3, 6], state: "ufo:stellar_field_generator_t1"},
        {pos: [5, 3, 6], state: "ae2:quartz_vibrant_glass"},
        {pos: [1, 3, 7], state: "ae2:quartz_vibrant_glass"},
        {pos: [5, 3, 7], state: "ae2:quartz_vibrant_glass"},
        {pos: [1, 3, 8], state: "ufo:quantum_hyper_mechanical_casing"},
        {pos: [2, 3, 8], state: "ae2:fluix_block"},
        {pos: [3, 3, 8], state: "ae2:quartz_vibrant_glass"},
        {pos: [4, 3, 8], state: "ae2:fluix_block"},
        {pos: [5, 3, 8], state: "ufo:quantum_hyper_mechanical_casing"},
        {pos: [0, 4, 0], state: "ufo:quantum_hyper_mechanical_casing"},
        {pos: [1, 4, 0], state: "ufo:quantum_hyper_mechanical_casing"},
        {pos: [2, 4, 0], state: "ae2:quartz_vibrant_glass"},
        {pos: [3, 4, 0], state: "ufo:quantum_hyper_mechanical_casing"},
        {pos: [4, 4, 0], state: "ae2:quartz_vibrant_glass"},
        {pos: [5, 4, 0], state: "ufo:quantum_hyper_mechanical_casing"},
        {pos: [6, 4, 0], state: "ufo:quantum_hyper_mechanical_casing"},
        {pos: [0, 4, 1], state: "ufo:quantum_hyper_mechanical_casing"},
        {pos: [1, 4, 1], state: "ufo:quantum_hyper_mechanical_casing"},
        {pos: [2, 4, 1], state: "ae2:quartz_vibrant_glass"},
        {pos: [3, 4, 1], state: "ufo:quantum_hyper_mechanical_casing"},
        {pos: [4, 4, 1], state: "ae2:quartz_vibrant_glass"},
        {pos: [5, 4, 1], state: "ufo:quantum_hyper_mechanical_casing"},
        {pos: [6, 4, 1], state: "ufo:quantum_hyper_mechanical_casing"},
        {pos: [0, 4, 2], state: "ufo:quantum_hyper_mechanical_casing"},
        {pos: [1, 4, 2], state: "ufo:quantum_hyper_mechanical_casing"},
        {pos: [2, 4, 2], state: "ae2:quartz_vibrant_glass"},
        {pos: [3, 4, 2], state: "ufo:quantum_hyper_mechanical_casing"},
        {pos: [4, 4, 2], state: "ae2:quartz_vibrant_glass"},
        {pos: [5, 4, 2], state: "ufo:quantum_hyper_mechanical_casing"},
        {pos: [6, 4, 2], state: "ufo:quantum_hyper_mechanical_casing"},
        {pos: [0, 4, 3], state: "ufo:quantum_hyper_mechanical_casing"},
        {pos: [1, 4, 3], state: "ufo:quantum_hyper_mechanical_casing"},
        {pos: [2, 4, 3], state: "ufo:quantum_hyper_mechanical_casing"},
        {pos: [3, 4, 3], state: "ufo:quantum_hyper_mechanical_casing"},
        {pos: [4, 4, 3], state: "ufo:quantum_hyper_mechanical_casing"},
        {pos: [5, 4, 3], state: "ufo:quantum_hyper_mechanical_casing"},
        {pos: [6, 4, 3], state: "ufo:quantum_hyper_mechanical_casing"},
        {pos: [1, 4, 4], state: "ufo:quantum_hyper_mechanical_casing"},
        {pos: [2, 4, 4], state: "ufo:quantum_hyper_mechanical_casing"},
        {pos: [3, 4, 4], state: "ufo:quantum_hyper_mechanical_casing"},
        {pos: [4, 4, 4], state: "ufo:quantum_hyper_mechanical_casing"},
        {pos: [5, 4, 4], state: "ufo:quantum_hyper_mechanical_casing"},
        {pos: [1, 4, 5], state: "ufo:quantum_hyper_mechanical_casing"},
        {pos: [2, 4, 5], state: "ae2:quartz_block"},
        {pos: [3, 4, 5], state: "ae2:quartz_block"},
        {pos: [4, 4, 5], state: "ae2:quartz_block"},
        {pos: [5, 4, 5], state: "ufo:quantum_hyper_mechanical_casing"},
        {pos: [1, 4, 6], state: "ufo:quantum_hyper_mechanical_casing"},
        {pos: [2, 4, 6], state: "ae2:quartz_block"},
        {pos: [3, 4, 6], state: "ae2:quartz_block"},
        {pos: [4, 4, 6], state: "ae2:quartz_block"},
        {pos: [5, 4, 6], state: "ufo:quantum_hyper_mechanical_casing"},
        {pos: [1, 4, 7], state: "ufo:quantum_hyper_mechanical_casing"},
        {pos: [2, 4, 7], state: "ae2:quartz_block"},
        {pos: [3, 4, 7], state: "ae2:quartz_block"},
        {pos: [4, 4, 7], state: "ae2:quartz_block"},
        {pos: [5, 4, 7], state: "ufo:quantum_hyper_mechanical_casing"},
        {pos: [1, 4, 8], state: "ufo:quantum_hyper_mechanical_casing"},
        {pos: [2, 4, 8], state: "ufo:quantum_hyper_mechanical_casing"},
        {pos: [3, 4, 8], state: "ufo:quantum_hyper_mechanical_casing"},
        {pos: [4, 4, 8], state: "ufo:quantum_hyper_mechanical_casing"},
        {pos: [5, 4, 8], state: "ufo:quantum_hyper_mechanical_casing"}
    ],
    entities: [],
    palette: [
        "ufo:quantum_hyper_mechanical_casing",
        "ae2:fluix_block",
        "ufo:quantum_pattern_fabrication_matrix_controller",
        "ufo:quantum_grid_link",
        "ae2:quartz_vibrant_glass",
        "ufo:stellar_field_generator_t1",
        "ae2:quartz_block"
    ]
}
