{
    DataVersion: 3955,
    size: [13, 5, 5],
    data: [
        {pos: [1, 0, 0], state: "ufo:quantum_hyper_mechanical_casing"},
        {pos: [2, 0, 0], state: "ae2:quartz_block"},
        {pos: [3, 0, 0], state: "ae2:quartz_block"},
        {pos: [4, 0, 0], state: "ae2:quartz_block"},
        {pos: [5, 0, 0], state: "ae2:fluix_block"},
        {pos: [6, 0, 0], state: "ae2:fluix_block"},
        {pos: [7, 0, 0], state: "ae2:fluix_block"},
        {pos: [8, 0, 0], state: "ae2:quartz_block"},
        {pos: [9, 0, 0], state: "ae2:quartz_block"},
        {pos: [10, 0, 0], state: "ae2:quartz_block"},
        {pos: [11, 0, 0], state: "ufo:quantum_hyper_mechanical_casing"},
        {pos: [1, 0, 1], state: "ufo:quantum_hyper_mechanical_casing"},
        {pos: [2, 0, 1], state: "ufo:quantum_hyper_mechanical_casing"},
        {pos: [3, 0, 1], state: "ufo:quantum_hyper_mechanical_casing"},
        {pos: [4, 0, 1], state: "ufo:quantum_hyper_mechanical_casing"},
        {pos: [5, 0, 1], state: "ufo:quantum_hyper_mechanical_casing"},
        {pos: [6, 0, 1], state: "ufo:quantum_hyper_mechanical_casing"},
        {pos: [7, 0, 1], state: "ufo:quantum_hyper_mechanical_casing"},
        {pos: [8, 0, 1], state: "ufo:quantum_hyper_mechanical_casing"},
        {pos: [9, 0, 1], state: "ufo:quantum_hyper_mechanical_casing"},
        {pos: [10, 0, 1], state: "ufo:quantum_hyper_mechanical_casing"},
        {pos: [11, 0, 1], state: "ufo:quantum_hyper_mechanical_casing"},
        {pos: [0, 0, 2], state: "ufo:quantum_hyper_mechanical_casing"},
        {pos: [1, 0, 2], state: "ufo:quantum_hyper_mechanical_casing"},
        {pos: [2, 0, 2], state: "ufo:quantum_hyper_mechanical_casing"},
        {pos: [3, 0, 2], state: "ufo:quantum_hyper_mechanical_casing"},
        {pos: [4, 0, 2], state: "ufo:quantum_hyper_mechanical_casing"},
        {pos: [5, 0, 2], state: "ufo:quantum_hyper_mechanical_casing"},
        {pos: [6, 0, 2], state: "ufo:quantum_hyper_mechanical_casing"},
        {pos: [7, 0, 2], state: "ufo:quantum_hyper_mechanical_casing"},
        {pos: [8, 0, 2], state: "ufo:quantum_hyper_mechanical_casing"},
        {pos: [9, 0, 2], state: "ufo:quantum_hyper_mechanical_casing"},
        {pos: [10, 0, 2], state: "ufo:quantum_hyper_mechanical_casing"},
        {pos: [11, 0, 2], state: "ufo:quantum_hyper_mechanical_casing"},
        {pos: [12, 0, 2], state: "ufo:quantum_hyper_mechanical_casing"},
        {pos: [1, 0, 3], state: "ufo:quantum_hyper_mechanical_casing"},
        {pos: [2, 0, 3], state: "ufo:quantum_hyper_mechanical_casing"},
        {pos: [3, 0, 3], state: "ufo:quantum_hyper_mechanical_casing"},
        {pos: [4, 0, 3], state: "ufo:quantum_hyper_mechanical_casing"},
        {pos: [5, 0, 3], state: "ufo:quantum_hyper_mechanical_casing"},
        {pos: [6, 0, 3], state: "ufo:quantum_hyper_mechanical_casing"},
        {pos: [7, 0, 3], state: "ufo:quantum_hyper_mechanical_casing"},
        {pos: [8, 0, 3], state: "ufo:quantum_hyper_mechanical_casing"},
        {pos: [9, 0, 3], state: "ufo:quantum_hyper_mechanical_casing"},
        {pos: [10, 0, 3], state: "ufo:quantum_hyper_mechanical_casing"},
        {pos: [11, 0, 3], state: "ufo:quantum_hyper_mechanical_casing"},
        {pos: [1, 0, 4], state: "ufo:quantum_hyper_mechanical_casing"},
        {pos: [2, 0, 4], state: "ae2:quartz_block"},
        {pos: [3, 0, 4], state: "ae2:quartz_block"},
        {pos: [4, 0, 4], state: "ae2:quartz_block"},
        {pos: [5, 0, 4], state: "ae2:fluix_block"},
        {pos: [6, 0, 4], state: "ae2:fluix_block"},
        {pos: [7, 0, 4], state: "ae2:fluix_block"},
        {pos: [8, 0, 4], state: "ae2:quartz_block"},
        {pos: [9, 0, 4], state: "ae2:quartz_block"},
        {pos: [10, 0, 4], state: "ae2:quartz_block"},
        {pos: [11, 0, 4], state: "ufo:quantum_hyper_mechanical_casing"},
        {pos: [1, 1, 0], state: "ufo:quantum_hyper_mechanical_casing"},
        {pos: [2, 1, 0], state: "ae2:quartz_vibrant_glass"},
        {pos: [3, 1, 0], state: "ae2:quartz_vibrant_glass"},
        {pos: [4, 1, 0], state: "ae2:quartz_vibrant_glass"},
        {pos: [5, 1, 0], state: "ufo:quantum_hyper_mechanical_casing"},
        {pos: [6, 1, 0], state: "ufo:me_massive_fluid_hatch"},
        {pos: [7, 1, 0], state: "ufo:quantum_hyper_mechanical_casing"},
        {pos: [8, 1, 0], state: "ae2:quartz_vibrant_glass"},
        {pos: [9, 1, 0], state: "ae2:quartz_vibrant_glass"},
        {pos: [10, 1, 0], state: "ae2:quartz_vibrant_glass"},
        {pos: [11, 1, 0], state: "ufo:quantum_hyper_mechanical_casing"},
        {pos: [0, 1, 1], state: "ufo:quantum_hyper_mechanical_casing"},
        {pos: [1, 1, 1], state: "ufo:quantum_hyper_mechanical_casing"},
        {pos: [2, 1, 1], state: "ufo:stellar_field_generator_t1"},
        {pos: [3, 1, 1], state: "ufo:stellar_field_generator_t1"},
        {pos: [4, 1, 1], state: "ufo:stellar_field_generator_t1"},
        {pos: [8, 1, 1], state: "ufo:stellar_field_generator_t1"},
        {pos: [9, 1, 1], state: "ufo:stellar_field_generator_t1"},
        {pos: [10, 1, 1], state: "ufo:stellar_field_generator_t1"},
        {pos: [11, 1, 1], state: "ufo:quantum_hyper_mechanical_casing"},
        {pos: [12, 1, 1], state: "ufo:quantum_hyper_mechanical_casing"},
        {pos: [0, 1, 2], state: "ufo:quantum_hyper_mechanical_casing"},
        {pos: [1, 1, 2], state: "ufo:quantum_hyper_mechanical_casing"},
        {pos: [2, 1, 2], state: "ufo:stellar_field_generator_t1"},
        {pos: [3, 1, 2], state: "ufo:stellar_field_generator_t1"},
        {pos: [4, 1, 2], state: "ufo:stellar_field_generator_t1"},
        {pos: [6, 1, 2], state: "ufo:stellar_field_generator_t1"},
        {pos: [8, 1, 2], state: "ufo:stellar_field_generator_t1"},
        {pos: [9, 1, 2], state: "ufo:stellar_field_generator_t1"},
        {pos: [10, 1, 2], state: "ufo:stellar_field_generator_t1"},
        {pos: [11, 1, 2], state: "ufo:quantum_hyper_mechanical_casing"},
        {pos: [12, 1, 2], state: "ufo:quantum_hyper_mechanical_casing"},
        {pos: [0, 1, 3], state: "ufo:quantum_hyper_mechanical_casing"},
        {pos: [1, 1, 3], state: "ufo:quantum_hyper_mechanical_casing"},
        {pos: [2, 1, 3], state: "ufo:stellar_field_generator_t1"},
        {pos: [3, 1, 3], state: "ufo:stellar_field_generator_t1"},
        {pos: [4, 1, 3], state: "ufo:stellar_field_generator_t1"},
        {pos: [8, 1, 3], state: "ufo:stellar_field_generator_t1"},
        {pos: [9, 1, 3], state: "ufo:stellar_field_generator_t1"},
        {pos: [10, 1, 3], state: "ufo:stellar_field_generator_t1"},
        {pos: [11, 1, 3], state: "ufo:quantum_hyper_mechanical_casing"},
        {pos: [12, 1, 3], state: "ufo:quantum_hyper_mechanical_casing"},
        {pos: [1, 1, 4], state: "ufo:quantum_hyper_mechanical_casing"},
        {pos: [2, 1, 4], state: "ae2:quartz_vibrant_glass"},
        {pos: [3, 1, 4], state: "ae2:quartz_vibrant_glass"},
        {pos: [4, 1, 4], state: "ae2:quartz_vibrant_glass"},
        {pos: [5, 1, 4], state: "ufo:quantum_hyper_mechanical_casing"},
        {pos: [6, 1, 4], state: "ufo:quantum_hyper_mechanical_casing"},
        {pos: [7, 1, 4], state: "ufo:quantum_hyper_mechanical_casing"},
        {pos: [8, 1, 4], state: "ae2:quartz_vibrant_glass"},
        {pos: [9, 1, 4], state: "ae2:quartz_vibrant_glass"},
        {pos: [10, 1, 4], state: "ae2:quartz_vibrant_glass"},
        {pos: [11, 1, 4], state: "ufo:quantum_hyper_mechanical_casing"},
        {pos: [0, 2, 0], state: "ufo:quantum_hyper_mechanical_casing"},
        {pos: [1, 2, 0], state: "ufo:quantum_hyper_mechanical_casing"},
        {pos: [2, 2, 0], state: "ufo:quantum_hyper_mechanical_casing"},
        {pos: [3, 2, 0], state: "ufo:quantum_hyper_mechanical_casing"},
        {pos: [4, 2, 0], state: "ufo:quantum_hyper_mechanical_casing"},
        {pos: [5, 2, 0], state: "ufo:ae_energy_input_hatch"},
        {pos: [6, 2, 0], state: "ufo:quantum_slicer_controller"},
        {pos: [7, 2, 0], state: "ufo:quantum_hyper_mechanical_casing"},
        {pos: [8, 2, 0], state: "ufo:quantum_hyper_mechanical_casing"},
        {pos: [9, 2, 0], state: "ufo:quantum_hyper_mechanical_casing"},
        {pos: [10, 2, 0], state: "ufo:quantum_hyper_mechanical_casing"},
        {pos: [11, 2, 0], state: "ufo:quantum_hyper_mechanical_casing"},
        {pos: [12, 2, 0], state: "ufo:quantum_hyper_mechanical_casing"},
        {pos: [0, 2, 1], state: "ufo:quantum_hyper_mechanical_casing"},
        {pos: [1, 2, 1], state: "ufo:quantum_hyper_mechanical_casing"},
        {pos: [2, 2, 1], state: "ufo:stellar_field_generator_t1"},
        {pos: [3, 2, 1], state: "ufo:stellar_field_generator_t1"},
        {pos: [4, 2, 1], state: "ufo:stellar_field_generator_t1"},
        {pos: [8, 2, 1], state: "ufo:stellar_field_generator_t1"},
        {pos: [9, 2, 1], state: "ufo:stellar_field_generator_t1"},
        {pos: [10, 2, 1], state: "ufo:stellar_field_generator_t1"},
        {pos: [11, 2, 1], state: "ufo:quantum_hyper_mechanical_casing"},
        {pos: [12, 2, 1], state: "ufo:quantum_hyper_mechanical_casing"},
        {pos: [0, 2, 2], state: "ufo:stellar_field_generator_t1"},
        {pos: [1, 2, 2], state: "ufo:stellar_field_generator_t1"},
        {pos: [2, 2, 2], state: "ufo:stellar_field_generator_t1"},
        {pos: [3, 2, 2], state: "ufo:stellar_field_generator_t1"},
        {pos: [4, 2, 2], state: "ufo:stellar_field_generator_t1"},
        {pos: [6, 2, 2], state: "ufo:stellar_field_generator_t1"},
        {pos: [8, 2, 2], state: "ufo:stellar_field_generator_t1"},
        {pos: [9, 2, 2], state: "ufo:stellar_field_generator_t1"},
        {pos: [10, 2, 2], state: "ufo:stellar_field_generator_t1"},
        {pos: [11, 2, 2], state: "ufo:stellar_field_generator_t1"},
        {pos: [12, 2, 2], state: "ufo:stellar_field_generator_t1"},
        {pos: [0, 2, 3], state: "ufo:quantum_hyper_mechanical_casing"},
        {pos: [1, 2, 3], state: "ufo:quantum_hyper_mechanical_casing"},
        {pos: [2, 2, 3], state: "ufo:stellar_field_generator_t1"},
        {pos: [3, 2, 3], state: "ufo:stellar_field_generator_t1"},
        {pos: [4, 2, 3], state: "ufo:stellar_field_generator_t1"},
        {pos: [8, 2, 3], state: "ufo:stellar_field_generator_t1"},
        {pos: [9, 2, 3], state: "ufo:stellar_field_generator_t1"},
        {pos: [10, 2, 3], state: "ufo:stellar_field_generator_t1"},
        {pos: [11, 2, 3], state: "ufo:quantum_hyper_mechanical_casing"},
        {pos: [12, 2, 3], state: "ufo:quantum_hyper_mechanical_casing"},
        {pos: [0, 2, 4], state: "ufo:quantum_hyper_mechanical_casing"},
        {pos: [1, 2, 4], state: "ufo:quantum_hyper_mechanical_casing"},
        {pos: [2, 2, 4], state: "ufo:quantum_hyper_mechanical_casing"},
        {pos: [3, 2, 4], state: "ufo:quantum_hyper_mechanical_casing"},
        {pos: [4, 2, 4], state: "ufo:quantum_hyper_mechanical_casing"},
        {pos: [5, 2, 4], state: "ufo:quantum_hyper_mechanical_casing"},
        {pos: [6, 2, 4], state: "ufo:quantum_hyper_mechanical_casing"},
        {pos: [7, 2, 4], state: "ufo:quantum_hyper_mechanical_casing"},
        {pos: [8, 2, 4], state: "ufo:quantum_hyper_mechanical_casing"},
        {pos: [9, 2, 4], state: "ufo:quantum_hyper_mechanical_casing"},
        {pos: [10, 2, 4], state: "ufo:quantum_hyper_mechanical_casing"},
        {pos: [11, 2, 4], state: "ufo:quantum_hyper_mechanical_casing"},
        {pos: [12, 2, 4], state: "ufo:quantum_hyper_mechanical_casing"},
        {pos: [1, 3, 0], state: "ufo:quantum_hyper_mechanical_casing"},
        {pos: [2, 3, 0], state: "ae2:quartz_vibrant_glass"},
        {pos: [3, 3, 0], state: "ae2:quartz_vibrant_glass"},
        {pos: [4, 3, 0], state: "ae2:quartz_vibrant_glass"},
        {pos: [5, 3, 0], state: "ufo:quantum_hyper_mechanical_casing"},
        {pos: [6, 3, 0], state: "ufo:quantum_hyper_mechanical_casing"},
        {pos: [7, 3, 0], state: "ufo:quantum_hyper_mechanical_casing"},
        {pos: [8, 3, 0], state: "ae2:quartz_vibrant_glass"},
        {pos: [9, 3, 0], state: "ae2:quartz_vibrant_glass"},
        {pos: [10, 3, 0], state: "ae2:quartz_vibrant_glass"},
        {pos: [11, 3, 0], state: "ufo:quantum_hyper_mechanical_casing"},
        {pos: [0, 3, 1], state: "ufo:quantum_hyper_mechanical_casing"},
        {pos: [1, 3, 1], state: "ufo:quantum_hyper_mechanical_casing"},
        {pos: [2, 3, 1], state: "ufo:stellar_field_generator_t1"},
        {pos: [3, 3, 1], state: "ufo:stellar_field_generator_t1"},
        {pos: [4, 3, 1], state: "ufo:stellar_field_generator_t1"},
        {pos: [8, 3, 1], state: "ufo:stellar_field_generator_t1"},
        {pos: [9, 3, 1], state: "ufo:stellar_field_generator_t1"},
        {pos: [10, 3, 1], state: "ufo:stellar_field_generator_t1"},
        {pos: [11, 3, 1], state: "ufo:quantum_hyper_mechanical_casing"},
        {pos: [12, 3, 1], state: "ufo:quantum_hyper_mechanical_casing"},
        {pos: [0, 3, 2], state: "ufo:quantum_hyper_mechanical_casing"},
        {pos: [1, 3, 2], state: "ufo:quantum_hyper_mechanical_casing"},
        {pos: [2, 3, 2], state: "ufo:stellar_field_generator_t1"},
        {pos: [3, 3, 2], state: "ufo:stellar_field_generator_t1"},
        {pos: [4, 3, 2], state: "ufo:stellar_field_generator_t1"},
        {pos: [6, 3, 2], state: "ufo:stellar_field_generator_t1"},
        {pos: [8, 3, 2], state: "ufo:stellar_field_generator_t1"},
        {pos: [9, 3, 2], state: "ufo:stellar_field_generator_t1"},
        {pos: [10, 3, 2], state: "ufo:stellar_field_generator_t1"},
        {pos: [11, 3, 2], state: "ufo:quantum_hyper_mechanical_casing"},
        {pos: [12, 3, 2], state: "ufo:quantum_hyper_mechanical_casing"},
        {pos: [0, 3, 3], state: "ufo:quantum_hyper_mechanical_casing"},
        {pos: [1, 3, 3], state: "ufo:quantum_hyper_mechanical_casing"},
        {pos: [2, 3, 3], state: "ufo:stellar_field_generator_t1"},
        {pos: [3, 3, 3], state: "ufo:stellar_field_generator_t1"},
        {pos: [4, 3, 3], state: "ufo:stellar_field_generator_t1"},
        {pos: [8, 3, 3], state: "ufo:stellar_field_generator_t1"},
        {pos: [9, 3, 3], state: "ufo:stellar_field_generator_t1"},
        {pos: [10, 3, 3], state: "ufo:stellar_field_generator_t1"},
        {pos: [11, 3, 3], state: "ufo:quantum_hyper_mechanical_casing"},
        {pos: [12, 3, 3], state: "ufo:quantum_hyper_mechanical_casing"},
        {pos: [1, 3, 4], state: "ufo:quantum_hyper_mechanical_casing"},
        {pos: [2, 3, 4], state: "ae2:quartz_vibrant_glass"},
        {pos: [3, 3, 4], state: "ae2:quartz_vibrant_glass"},
        {pos: [4, 3, 4], state: "ae2:quartz_vibrant_glass"},
        {pos: [5, 3, 4], state: "ufo:quantum_hyper_mechanical_casing"},
        {pos: [6, 3, 4], state: "ufo:quantum_hyper_mechanical_casing"},
        {pos: [7, 3, 4], state: "ufo:quantum_hyper_mechanical_casing"},
        {pos: [8, 3, 4], state: "ae2:quartz_vibrant_glass"},
        {pos: [9, 3, 4], state: "ae2:quartz_vibrant_glass"},
        {pos: [10, 3, 4], state: "ae2:quartz_vibrant_glass"},
        {pos: [11, 3, 4], state: "ufo:quantum_hyper_mechanical_casing"},
        {pos: [1, 4, 0], state: "ufo:quantum_hyper_mechanical_casing"},
        {pos: [2, 4, 0], state: "ae2:quartz_block"},
        {pos: [3, 4, 0], state: "ae2:quartz_block"},
        {pos: [4, 4, 0], state: "ae2:quartz_block"},
        {pos: [5, 4, 0], state: "ae2:fluix_block"},
        {pos: [6, 4, 0], state: "ae2:fluix_block"},
        {pos: [7, 4, 0], state: "ae2:fluix_block"},
        {pos: [8, 4, 0], state: "ae2:quartz_block"},
        {pos: [9, 4, 0], state: "ae2:quartz_block"},
        {pos: [10, 4, 0], state: "ae2:quartz_block"},
        {pos: [11, 4, 0], state: "ufo:quantum_hyper_mechanical_casing"},
        {pos: [1, 4, 1], state: "ufo:quantum_hyper_mechanical_casing"},
        {pos: [2, 4, 1], state: "ae2:quartz_vibrant_glass"},
        {pos: [3, 4, 1], state: "ae2:quartz_vibrant_glass"},
        {pos: [4, 4, 1], state: "ae2:quartz_vibrant_glass"},
        {pos: [5, 4, 1], state: "ufo:quantum_hyper_mechanical_casing"},
        {pos: [6, 4, 1], state: "ufo:quantum_hyper_mechanical_casing"},
        {pos: [7, 4, 1], state: "ufo:quantum_hyper_mechanical_casing"},
        {pos: [8, 4, 1], state: "ae2:quartz_vibrant_glass"},
        {pos: [9, 4, 1], state: "ae2:quartz_vibrant_glass"},
        {pos: [10, 4, 1], state: "ae2:quartz_vibrant_glass"},
        {pos: [11, 4, 1], state: "ufo:quantum_hyper_mechanical_casing"},
        {pos: [0, 4, 2], state: "ufo:quantum_hyper_mechanical_casing"},
        {pos: [1, 4, 2], state: "ufo:quantum_hyper_mechanical_casing"},
        {pos: [2, 4, 2], state: "ufo:quantum_hyper_mechanical_casing"},
        {pos: [3, 4, 2], state: "ufo:quantum_hyper_mechanical_casing"},
        {pos: [4, 4, 2], state: "ufo:quantum_hyper_mechanical_casing"},
        {pos: [5, 4, 2], state: "ufo:quantum_hyper_mechanical_casing"},
        {pos: [6, 4, 2], state: "ufo:quantum_hyper_mechanical_casing"},
        {pos: [7, 4, 2], state: "ufo:quantum_hyper_mechanical_casing"},
        {pos: [8, 4, 2], state: "ufo:quantum_hyper_mechanical_casing"},
        {pos: [9, 4, 2], state: "ufo:quantum_hyper_mechanical_casing"},
        {pos: [10, 4, 2], state: "ufo:quantum_hyper_mechanical_casing"},
        {pos: [11, 4, 2], state: "ufo:quantum_hyper_mechanical_casing"},
        {pos: [12, 4, 2], state: "ufo:quantum_hyper_mechanical_casing"},
        {pos: [1, 4, 3], state: "ufo:quantum_hyper_mechanical_casing"},
        {pos: [2, 4, 3], state: "ae2:quartz_vibrant_glass"},
        {pos: [3, 4, 3], state: "ae2:quartz_vibrant_glass"},
        {pos: [4, 4, 3], state: "ae2:quartz_vibrant_glass"},
        {pos: [5, 4, 3], state: "ufo:quantum_hyper_mechanical_casing"},
        {pos: [6, 4, 3], state: "ufo:quantum_hyper_mechanical_casing"},
        {pos: [7, 4, 3], state: "ufo:quantum_hyper_mechanical_casing"},
        {pos: [8, 4, 3], state: "ae2:quartz_vibrant_glass"},
        {pos: [9, 4, 3], state: "ae2:quartz_vibrant_glass"},
        {pos: [10, 4, 3], state: "ae2:quartz_vibrant_glass"},
        {pos: [11, 4, 3], state: "ufo:quantum_hyper_mechanical_casing"},
        {pos: [1, 4, 4], state: "ufo:quantum_hyper_mechanical_casing"},
        {pos: [2, 4, 4], state: "ae2:quartz_block"},
        {pos: [3, 4, 4], state: "ae2:quartz_block"},
        {pos: [4, 4, 4], state: "ae2:quartz_block"},
        {pos: [5, 4, 4], state: "ae2:fluix_block"},
        {pos: [6, 4, 4], state: "ae2:fluix_block"},
        {pos: [7, 4, 4], state: "ae2:fluix_block"},
        {pos: [8, 4, 4], state: "ae2:quartz_block"},
        {pos: [9, 4, 4], state: "ae2:quartz_block"},
        {pos: [10, 4, 4], state: "ae2:quartz_block"},
        {pos: [11, 4, 4], state: "ufo:quantum_hyper_mechanical_casing"}
    ],
    entities: [],
    palette: [
        "ufo:quantum_hyper_mechanical_casing",
        "ae2:quartz_block",
        "ae2:fluix_block",
        "ae2:quartz_vibrant_glass",
        "ufo:me_massive_fluid_hatch",
        "ufo:stellar_field_generator_t1",
        "ufo:ae_energy_input_hatch",
        "ufo:quantum_slicer_controller"
    ]
}
