{
    DataVersion: 3955,
    size: [9, 14, 9],
    data: [
        {pos: [0, 0, 0], state: "ufo:quantum_hyper_mechanical_casing"},
        {pos: [1, 0, 0], state: "ufo:quantum_hyper_mechanical_casing"},
        {pos: [2, 0, 0], state: "ufo:quantum_hyper_mechanical_casing"},
        {pos: [3, 0, 0], state: "ufo:quantum_hyper_mechanical_casing"},
        {pos: [4, 0, 0], state: "ufo:me_massive_fluid_hatch"},
        {pos: [5, 0, 0], state: "ufo:quantum_hyper_mechanical_casing"},
        {pos: [6, 0, 0], state: "ufo:quantum_hyper_mechanical_casing"},
        {pos: [7, 0, 0], state: "ufo:quantum_hyper_mechanical_casing"},
        {pos: [8, 0, 0], state: "ufo:quantum_hyper_mechanical_casing"},
        {pos: [0, 0, 1], state: "ufo:quantum_hyper_mechanical_casing"},
        {pos: [1, 0, 1], state: "ufo:quantum_hyper_mechanical_casing"},
        {pos: [2, 0, 1], state: "ufo:quantum_hyper_mechanical_casing"},
        {pos: [3, 0, 1], state: "ufo:quantum_hyper_mechanical_casing"},
        {pos: [4, 0, 1], state: "ufo:quantum_hyper_mechanical_casing"},
        {pos: [5, 0, 1], state: "ufo:quantum_hyper_mechanical_casing"},
        {pos: [6, 0, 1], state: "ufo:quantum_hyper_mechanical_casing"},
        {pos: [7, 0, 1], state: "ufo:quantum_hyper_mechanical_casing"},
        {pos: [8, 0, 1], state: "ufo:quantum_hyper_mechanical_casing"},
        {pos: [0, 0, 2], state: "ufo:quantum_hyper_mechanical_casing"},
        {pos: [1, 0, 2], state: "ufo:quantum_hyper_mechanical_casing"},
        {pos: [2, 0, 2], state: "ufo:quantum_hyper_mechanical_casing"},
        {pos: [3, 0, 2], state: "ufo:quantum_hyper_mechanical_casing"},
        {pos: [4, 0, 2], state: "ufo:quantum_hyper_mechanical_casing"},
        {pos: [5, 0, 2], state: "ufo:quantum_hyper_mechanical_casing"},
        {pos: [6, 0, 2], state: "ufo:quantum_hyper_mechanical_casing"},
        {pos: [7, 0, 2], state: "ufo:quantum_hyper_mechanical_casing"},
        {pos: [8, 0, 2], state: "ufo:quantum_hyper_mechanical_casing"},
        {pos: [0, 0, 3], state: "ufo:quantum_hyper_mechanical_casing"},
        {pos: [1, 0, 3], state: "ufo:quantum_hyper_mechanical_casing"},
        {pos: [2, 0, 3], state: "ufo:quantum_hyper_mechanical_casing"},
        {pos: [3, 0, 3], state: "ufo:quantum_hyper_mechanical_casing"},
        {pos: [4, 0, 3], state: "ufo:quantum_hyper_mechanical_casing"},
        {pos: [5, 0, 3], state: "ufo:quantum_hyper_mechanical_casing"},
        {pos: [6, 0, 3], state: "ufo:quantum_hyper_mechanical_casing"},
        {pos: [7, 0, 3], state: "ufo:quantum_hyper_mechanical_casing"},
        {pos: [8, 0, 3], state: "ufo:quantum_hyper_mechanical_casing"},
        {pos: [0, 0, 4], state: "ufo:quantum_hyper_mechanical_casing"},
        {pos: [1, 0, 4], state: "ufo:quantum_hyper_mechanical_casing"},
        {pos: [2, 0, 4], state: "ufo:quantum_hyper_mechanical_casing"},
        {pos: [3, 0, 4], state: "ufo:quantum_hyper_mechanical_casing"},
        {pos: [4, 0, 4], state: "ufo:quantum_hyper_mechanical_casing"},
        {pos: [5, 0, 4], state: "ufo:quantum_hyper_mechanical_casing"},
        {pos: [6, 0, 4], state: "ufo:quantum_hyper_mechanical_casing"},
        {pos: [7, 0, 4], state: "ufo:quantum_hyper_mechanical_casing"},
        {pos: [8, 0, 4], state: "ufo:quantum_hyper_mechanical_casing"},
        {pos: [0, 0, 5], state: "ufo:quantum_hyper_mechanical_casing"},
        {pos: [1, 0, 5], state: "ufo:quantum_hyper_mechanical_casing"},
        {pos: [2, 0, 5], state: "ufo:quantum_hyper_mechanical_casing"},
        {pos: [3, 0, 5], state: "ufo:quantum_hyper_mechanical_casing"},
        {pos: [4, 0, 5], state: "ufo:quantum_hyper_mechanical_casing"},
        {pos: [5, 0, 5], state: "ufo:quantum_hyper_mechanical_casing"},
        {pos: [6, 0, 5], state: "ufo:quantum_hyper_mechanical_casing"},
        {pos: [7, 0, 5], state: "ufo:quantum_hyper_mechanical_casing"},
        {pos: [8, 0, 5], state: "ufo:quantum_hyper_mechanical_casing"},
        {pos: [0, 0, 6], state: "ufo:quantum_hyper_mechanical_casing"},
        {pos: [1, 0, 6], state: "ufo:quantum_hyper_mechanical_casing"},
        {pos: [2, 0, 6], state: "ufo:quantum_hyper_mechanical_casing"},
        {pos: [3, 0, 6], state: "ufo:quantum_hyper_mechanical_casing"},
        {pos: [4, 0, 6], state: "ufo:quantum_hyper_mechanical_casing"},
        {pos: [5, 0, 6], state: "ufo:quantum_hyper_mechanical_casing"},
        {pos: [6, 0, 6], state: "ufo:quantum_hyper_mechanical_casing"},
        {pos: [7, 0, 6], state: "ufo:quantum_hyper_mechanical_casing"},
        {pos: [8, 0, 6], state: "ufo:quantum_hyper_mechanical_casing"},
        {pos: [0, 0, 7], state: "ufo:quantum_hyper_mechanical_casing"},
        {pos: [1, 0, 7], state: "ufo:quantum_hyper_mechanical_casing"},
        {pos: [2, 0, 7], state: "ufo:quantum_hyper_mechanical_casing"},
        {pos: [3, 0, 7], state: "ufo:quantum_hyper_mechanical_casing"},
        {pos: [4, 0, 7], state: "ufo:quantum_hyper_mechanical_casing"},
        {pos: [5, 0, 7], state: "ufo:quantum_hyper_mechanical_casing"},
        {pos: [6, 0, 7], state: "ufo:quantum_hyper_mechanical_casing"},
        {pos: [7, 0, 7], state: "ufo:quantum_hyper_mechanical_casing"},
        {pos: [8, 0, 7], state: "ufo:quantum_hyper_mechanical_casing"},
        {pos: [0, 0, 8], state: "ufo:quantum_hyper_mechanical_casing"},
        {pos: [1, 0, 8], state: "ufo:quantum_hyper_mechanical_casing"},
        {pos: [2, 0, 8], state: "ufo:quantum_hyper_mechanical_casing"},
        {pos: [3, 0, 8], state: "ufo:quantum_hyper_mechanical_casing"},
        {pos: [4, 0, 8], state: "ufo:quantum_hyper_mechanical_casing"},
        {pos: [5, 0, 8], state: "ufo:quantum_hyper_mechanical_casing"},
        {pos: [6, 0, 8], state: "ufo:quantum_hyper_mechanical_casing"},
        {pos: [7, 0, 8], state: "ufo:quantum_hyper_mechanical_casing"},
        {pos: [8, 0, 8], state: "ufo:quantum_hyper_mechanical_casing"},
        {pos: [2, 1, 0], state: "ufo:quantum_hyper_mechanical_casing"},
        {pos: [3, 1, 0], state: "ufo:ae_energy_input_hatch"},
        {pos: [4, 1, 0], state: "ufo:quantum_cryoforge_controller"},
        {pos: [5, 1, 0], state: "ufo:quantum_hyper_mechanical_casing"},
        {pos: [6, 1, 0], state: "ufo:quantum_hyper_mechanical_casing"},
        {pos: [1, 1, 1], state: "ufo:quantum_hyper_mechanical_casing"},
        {pos: [2, 1, 1], state: "minecraft:blue_ice"},
        {pos: [3, 1, 1], state: "minecraft:blue_ice"},
        {pos: [4, 1, 1], state: "minecraft:blue_ice"},
        {pos: [5, 1, 1], state: "minecraft:blue_ice"},
        {pos: [6, 1, 1], state: "minecraft:blue_ice"},
        {pos: [7, 1, 1], state: "ufo:quantum_hyper_mechanical_casing"},
        {pos: [0, 1, 2], state: "ufo:quantum_hyper_mechanical_casing"},
        {pos: [1, 1, 2], state: "minecraft:blue_ice"},
        {pos: [2, 1, 2], state: "minecraft:blue_ice"},
        {pos: [3, 1, 2], state: "minecraft:blue_ice"},
        {pos: [4, 1, 2], state: "minecraft:blue_ice"},
        {pos: [5, 1, 2], state: "minecraft:blue_ice"},
        {pos: [6, 1, 2], state: "minecraft:blue_ice"},
        {pos: [7, 1, 2], state: "minecraft:blue_ice"},
        {pos: [8, 1, 2], state: "ufo:quantum_hyper_mechanical_casing"},
        {pos: [0, 1, 3], state: "ufo:quantum_hyper_mechanical_casing"},
        {pos: [1, 1, 3], state: "minecraft:blue_ice"},
        {pos: [2, 1, 3], state: "minecraft:blue_ice"},
        {pos: [3, 1, 3], state: "ufo:stellar_field_generator_t1"},
        {pos: [4, 1, 3], state: "minecraft:blue_ice"},
        {pos: [5, 1, 3], state: "ufo:stellar_field_generator_t1"},
        {pos: [6, 1, 3], state: "minecraft:blue_ice"},
        {pos: [7, 1, 3], state: "minecraft:blue_ice"},
        {pos: [8, 1, 3], state: "ufo:quantum_hyper_mechanical_casing"},
        {pos: [0, 1, 4], state: "ufo:quantum_hyper_mechanical_casing"},
        {pos: [1, 1, 4], state: "minecraft:blue_ice"},
        {pos: [2, 1, 4], state: "minecraft:blue_ice"},
        {pos: [3, 1, 4], state: "minecraft:blue_ice"},
        {pos: [4, 1, 4], state: "ufo:stellar_field_generator_t1"},
        {pos: [5, 1, 4], state: "minecraft:blue_ice"},
        {pos: [6, 1, 4], state: "minecraft:blue_ice"},
        {pos: [7, 1, 4], state: "minecraft:blue_ice"},
        {pos: [8, 1, 4], state: "ufo:quantum_hyper_mechanical_casing"},
        {pos: [0, 1, 5], state: "ufo:quantum_hyper_mechanical_casing"},
        {pos: [1, 1, 5], state: "minecraft:blue_ice"},
        {pos: [2, 1, 5], state: "minecraft:blue_ice"},
        {pos: [3, 1, 5], state: "ufo:stellar_field_generator_t1"},
        {pos: [4, 1, 5], state: "minecraft:blue_ice"},
        {pos: [5, 1, 5], state: "ufo:stellar_field_generator_t1"},
        {pos: [6, 1, 5], state: "minecraft:blue_ice"},
        {pos: [7, 1, 5], state: "minecraft:blue_ice"},
        {pos: [8, 1, 5], state: "ufo:quantum_hyper_mechanical_casing"},
        {pos: [0, 1, 6], state: "ufo:quantum_hyper_mechanical_casing"},
        {pos: [1, 1, 6], state: "minecraft:blue_ice"},
        {pos: [2, 1, 6], state: "minecraft:blue_ice"},
        {pos: [3, 1, 6], state: "minecraft:blue_ice"},
        {pos: [4, 1, 6], state: "minecraft:blue_ice"},
        {pos: [5, 1, 6], state: "minecraft:blue_ice"},
        {pos: [6, 1, 6], state: "minecraft:blue_ice"},
        {pos: [7, 1, 6], state: "minecraft:blue_ice"},
        {pos: [8, 1, 6], state: "ufo:quantum_hyper_mechanical_casing"},
        {pos: [1, 1, 7], state: "ufo:quantum_hyper_mechanical_casing"},
        {pos: [2, 1, 7], state: "minecraft:blue_ice"},
        {pos: [3, 1, 7], state: "minecraft:blue_ice"},
        {pos: [4, 1, 7], state: "minecraft:blue_ice"},
        {pos: [5, 1, 7], state: "minecraft:blue_ice"},
        {pos: [6, 1, 7], state: "minecraft:blue_ice"},
        {pos: [7, 1, 7], state: "ufo:quantum_hyper_mechanical_casing"},
        {pos: [2, 1, 8], state: "ufo:quantum_hyper_mechanical_casing"},
        {pos: [3, 1, 8], state: "ufo:quantum_hyper_mechanical_casing"},
        {pos: [4, 1, 8], state: "ufo:quantum_hyper_mechanical_casing"},
        {pos: [5, 1, 8], state: "ufo:quantum_hyper_mechanical_casing"},
        {pos: [6, 1, 8], state: "ufo:quantum_hyper_mechanical_casing"},
        {pos: [2, 2, 0], state: "ufo:quantum_hyper_mechanical_casing"},
        {pos: [3, 2, 0], state: "ae2:quartz_vibrant_glass"},
        {pos: [4, 2, 0], state: "ufo:quantum_hyper_mechanical_casing"},
        {pos: [5, 2, 0], state: "ae2:quartz_vibrant_glass"},
        {pos: [6, 2, 0], state: "ufo:quantum_hyper_mechanical_casing"},
        {pos: [1, 2, 1], state: "ufo:quantum_hyper_mechanical_casing"},
        {pos: [7, 2, 1], state: "ufo:quantum_hyper_mechanical_casing"},
        {pos: [0, 2, 2], state: "ufo:quantum_hyper_mechanical_casing"},
        {pos: [8, 2, 2], state: "ufo:quantum_hyper_mechanical_casing"},
        {pos: [0, 2, 3], state: "ae2:quartz_vibrant_glass"},
        {pos: [3, 2, 3], state: "ufo:stellar_field_generator_t1"},
        {pos: [5, 2, 3], state: "ufo:stellar_field_generator_t1"},
        {pos: [8, 2, 3], state: "ae2:quartz_vibrant_glass"},
        {pos: [0, 2, 4], state: "ufo:quantum_hyper_mechanical_casing"},
        {pos: [4, 2, 4], state: "ufo:stellar_field_generator_t1"},
        {pos: [8, 2, 4], state: "ufo:quantum_hyper_mechanical_casing"},
        {pos: [0, 2, 5], state: "ae2:quartz_vibrant_glass"},
        {pos: [3, 2, 5], state: "ufo:stellar_field_generator_t1"},
        {pos: [5, 2, 5], state: "ufo:stellar_field_generator_t1"},
        {pos: [8, 2, 5], state: "ae2:quartz_vibrant_glass"},
        {pos: [0, 2, 6], state: "ufo:quantum_hyper_mechanical_casing"},
        {pos: [8, 2, 6], state: "ufo:quantum_hyper_mechanical_casing"},
        {pos: [1, 2, 7], state: "ufo:quantum_hyper_mechanical_casing"},
        {pos: [7, 2, 7], state: "ufo:quantum_hyper_mechanical_casing"},
        {pos: [2, 2, 8], state: "ufo:quantum_hyper_mechanical_casing"},
        {pos: [3, 2, 8], state: "ae2:quartz_vibrant_glass"},
        {pos: [4, 2, 8], state: "ufo:quantum_hyper_mechanical_casing"},
        {pos: [5, 2, 8], state: "ae2:quartz_vibrant_glass"},
        {pos: [6, 2, 8], state: "ufo:quantum_hyper_mechanical_casing"},
        {pos: [2, 3, 0], state: "ufo:quantum_hyper_mechanical_casing"},
        {pos: [3, 3, 0], state: "ae2:quartz_vibrant_glass"},
        {pos: [4, 3, 0], state: "ufo:quantum_hyper_mechanical_casing"},
        {pos: [5, 3, 0], state: "ae2:quartz_vibrant_glass"},
        {pos: [6, 3, 0], state: "ufo:quantum_hyper_mechanical_casing"},
        {pos: [1, 3, 1], state: "ufo:quantum_hyper_mechanical_casing"},
        {pos: [7, 3, 1], state: "ufo:quantum_hyper_mechanical_casing"},
        {pos: [0, 3, 2], state: "ufo:quantum_hyper_mechanical_casing"},
        {pos: [8, 3, 2], state: "ufo:quantum_hyper_mechanical_casing"},
        {pos: [0, 3, 3], state: "ae2:quartz_vibrant_glass"},
        {pos: [3, 3, 3], state: "ufo:stellar_field_generator_t1"},
        {pos: [5, 3, 3], state: "ufo:stellar_field_generator_t1"},
        {pos: [8, 3, 3], state: "ae2:quartz_vibrant_glass"},
        {pos: [0, 3, 4], state: "ufo:quantum_hyper_mechanical_casing"},
        {pos: [4, 3, 4], state: "ufo:stellar_field_generator_t1"},
        {pos: [8, 3, 4], state: "ufo:quantum_hyper_mechanical_casing"},
        {pos: [0, 3, 5], state: "ae2:quartz_vibrant_glass"},
        {pos: [3, 3, 5], state: "ufo:stellar_field_generator_t1"},
        {pos: [5, 3, 5], state: "ufo:stellar_field_generator_t1"},
        {pos: [8, 3, 5], state: "ae2:quartz_vibrant_glass"},
        {pos: [0, 3, 6], state: "ufo:quantum_hyper_mechanical_casing"},
        {pos: [8, 3, 6], state: "ufo:quantum_hyper_mechanical_casing"},
        {pos: [1, 3, 7], state: "ufo:quantum_hyper_mechanical_casing"},
        {pos: [7, 3, 7], state: "ufo:quantum_hyper_mechanical_casing"},
        {pos: [2, 3, 8], state: "ufo:quantum_hyper_mechanical_casing"},
        {pos: [3, 3, 8], state: "ae2:quartz_vibrant_glass"},
        {pos: [4, 3, 8], state: "ufo:quantum_hyper_mechanical_casing"},
        {pos: [5, 3, 8], state: "ae2:quartz_vibrant_glass"},
        {pos: [6, 3, 8], state: "ufo:quantum_hyper_mechanical_casing"},
        {pos: [2, 4, 0], state: "ufo:quantum_hyper_mechanical_casing"},
        {pos: [3, 4, 0], state: "ufo:quantum_hyper_mechanical_casing"},
        {pos: [4, 4, 0], state: "ufo:quantum_hyper_mechanical_casing"},
        {pos: [5, 4, 0], state: "ufo:quantum_hyper_mechanical_casing"},
        {pos: [6, 4, 0], state: "ufo:quantum_hyper_mechanical_casing"},
        {pos: [1, 4, 1], state: "ufo:quantum_hyper_mechanical_casing"},
        {pos: [7, 4, 1], state: "ufo:quantum_hyper_mechanical_casing"},
        {pos: [0, 4, 2], state: "ufo:quantum_hyper_mechanical_casing"},
        {pos: [8, 4, 2], state: "ufo:quantum_hyper_mechanical_casing"},
        {pos: [0, 4, 3], state: "ufo:quantum_hyper_mechanical_casing"},
        {pos: [3, 4, 3], state: "ufo:stellar_field_generator_t1"},
        {pos: [5, 4, 3], state: "ufo:stellar_field_generator_t1"},
        {pos: [8, 4, 3], state: "ufo:quantum_hyper_mechanical_casing"},
        {pos: [0, 4, 4], state: "ufo:quantum_hyper_mechanical_casing"},
        {pos: [4, 4, 4], state: "ufo:stellar_field_generator_t1"},
        {pos: [8, 4, 4], state: "ufo:quantum_hyper_mechanical_casing"},
        {pos: [0, 4, 5], state: "ufo:quantum_hyper_mechanical_casing"},
        {pos: [3, 4, 5], state: "ufo:stellar_field_generator_t1"},
        {pos: [5, 4, 5], state: "ufo:stellar_field_generator_t1"},
        {pos: [8, 4, 5], state: "ufo:quantum_hyper_mechanical_casing"},
        {pos: [0, 4, 6], state: "ufo:quantum_hyper_mechanical_casing"},
        {pos: [8, 4, 6], state: "ufo:quantum_hyper_mechanical_casing"},
        {pos: [1, 4, 7], state: "ufo:quantum_hyper_mechanical_casing"},
        {pos: [7, 4, 7], state: "ufo:quantum_hyper_mechanical_casing"},
        {pos: [2, 4, 8], state: "ufo:quantum_hyper_mechanical_casing"},
        {pos: [3, 4, 8], state: "ufo:quantum_hyper_mechanical_casing"},
        {pos: [4, 4, 8], state: "ufo:quantum_hyper_mechanical_casing"},
        {pos: [5, 4, 8], state: "ufo:quantum_hyper_mechanical_casing"},
        {pos: [6, 4, 8], state: "ufo:quantum_hyper_mechanical_casing"},
        {pos: [2, 5, 0], state: "ae2:quartz_block"},
        {pos: [3, 5, 0], state: "ae2:quartz_block"},
        {pos: [4, 5, 0], state: "ae2:quartz_block"},
        {pos: [5, 5, 0], state: "ae2:quartz_block"},
        {pos: [6, 5, 0], state: "ae2:quartz_block"},
        {pos: [1, 5, 1], state: "ae2:quartz_block"},
        {pos: [7, 5, 1], state: "ae2:quartz_block"},
        {pos: [0, 5, 2], state: "ae2:quartz_block"},
        {pos: [8, 5, 2], state: "ae2:quartz_block"},
        {pos: [0, 5, 3], state: "ae2:quartz_block"},
        {pos: [3, 5, 3], state: "ufo:stellar_field_generator_t1"},
        {pos: [5, 5, 3], state: "ufo:stellar_field_generator_t1"},
        {pos: [8, 5, 3], state: "ae2:quartz_block"},
        {pos: [0, 5, 4], state: "ae2:quartz_block"},
        {pos: [4, 5, 4], state: "ufo:stellar_field_generator_t1"},
        {pos: [8, 5, 4], state: "ae2:quartz_block"},
        {pos: [0, 5, 5], state: "ae2:quartz_block"},
        {pos: [3, 5, 5], state: "ufo:stellar_field_generator_t1"},
        {pos: [5, 5, 5], state: "ufo:stellar_field_generator_t1"},
        {pos: [8, 5, 5], state: "ae2:quartz_block"},
        {pos: [0, 5, 6], state: "ae2:quartz_block"},
        {pos: [8, 5, 6], state: "ae2:quartz_block"},
        {pos: [1, 5, 7], state: "ae2:quartz_block"},
        {pos: [7, 5, 7], state: "ae2:quartz_block"},
        {pos: [2, 5, 8], state: "ae2:quartz_block"},
        {pos: [3, 5, 8], state: "ae2:quartz_block"},
        {pos: [4, 5, 8], state: "ae2:quartz_block"},
        {pos: [5, 5, 8], state: "ae2:quartz_block"},
        {pos: [6, 5, 8], state: "ae2:quartz_block"},
        {pos: [2, 6, 0], state: "ae2:quartz_block"},
        {pos: [3, 6, 0], state: "ae2:quartz_block"},
        {pos: [4, 6, 0], state: "ae2:quartz_block"},
        {pos: [5, 6, 0], state: "ae2:quartz_block"},
        {pos: [6, 6, 0], state: "ae2:quartz_block"},
        {pos: [1, 6, 1], state: "ae2:quartz_block"},
        {pos: [7, 6, 1], state: "ae2:quartz_block"},
        {pos: [0, 6, 2], state: "ae2:quartz_block"},
        {pos: [8, 6, 2], state: "ae2:quartz_block"},
        {pos: [0, 6, 3], state: "ae2:quartz_block"},
        {pos: [3, 6, 3], state: "ufo:stellar_field_generator_t1"},
        {pos: [5, 6, 3], state: "ufo:stellar_field_generator_t1"},
        {pos: [8, 6, 3], state: "ae2:quartz_block"},
        {pos: [0, 6, 4], state: "ae2:quartz_block"},
        {pos: [4, 6, 4], state: "ufo:stellar_field_generator_t1"},
        {pos: [8, 6, 4], state: "ae2:quartz_block"},
        {pos: [0, 6, 5], state: "ae2:quartz_block"},
        {pos: [3, 6, 5], state: "ufo:stellar_field_generator_t1"},
        {pos: [5, 6, 5], state: "ufo:stellar_field_generator_t1"},
        {pos: [8, 6, 5], state: "ae2:quartz_block"},
        {pos: [0, 6, 6], state: "ae2:quartz_block"},
        {pos: [8, 6, 6], state: "ae2:quartz_block"},
        {pos: [1, 6, 7], state: "ae2:quartz_block"},
        {pos: [7, 6, 7], state: "ae2:quartz_block"},
        {pos: [2, 6, 8], state: "ae2:quartz_block"},
        {pos: [3, 6, 8], state: "ae2:quartz_block"},
        {pos: [4, 6, 8], state: "ae2:quartz_block"},
        {pos: [5, 6, 8], state: "ae2:quartz_block"},
        {pos: [6, 6, 8], state: "ae2:quartz_block"},
        {pos: [4, 7, 0], state: "ae2:quartz_block"},
        {pos: [2, 7, 1], state: "ae2:fluix_block"},
        {pos: [3, 7, 1], state: "ae2:fluix_block"},
        {pos: [4, 7, 1], state: "ae2:fluix_block"},
        {pos: [5, 7, 1], state: "ae2:fluix_block"},
        {pos: [6, 7, 1], state: "ae2:fluix_block"},
        {pos: [1, 7, 2], state: "ae2:fluix_block"},
        {pos: [2, 7, 2], state: "ae2:fluix_block"},
        {pos: [6, 7, 2], state: "ae2:fluix_block"},
        {pos: [7, 7, 2], state: "ae2:fluix_block"},
        {pos: [1, 7, 3], state: "ae2:fluix_block"},
        {pos: [3, 7, 3], state: "ufo:stellar_field_generator_t1"},
        {pos: [5, 7, 3], state: "ufo:stellar_field_generator_t1"},
        {pos: [7, 7, 3], state: "ae2:fluix_block"},
        {pos: [0, 7, 4], state: "ae2:quartz_block"},
        {pos: [1, 7, 4], state: "ae2:fluix_block"},
        {pos: [4, 7, 4], state: "ufo:stellar_field_generator_t1"},
        {pos: [7, 7, 4], state: "ae2:fluix_block"},
        {pos: [8, 7, 4], state: "ae2:quartz_block"},
        {pos: [1, 7, 5], state: "ae2:fluix_block"},
        {pos: [3, 7, 5], state: "ufo:stellar_field_generator_t1"},
        {pos: [5, 7, 5], state: "ufo:stellar_field_generator_t1"},
        {pos: [7, 7, 5], state: "ae2:fluix_block"},
        {pos: [1, 7, 6], state: "ae2:fluix_block"},
        {pos: [2, 7, 6], state: "ae2:fluix_block"},
        {pos: [6, 7, 6], state: "ae2:fluix_block"},
        {pos: [7, 7, 6], state: "ae2:fluix_block"},
        {pos: [2, 7, 7], state: "ae2:fluix_block"},
        {pos: [3, 7, 7], state: "ae2:fluix_block"},
        {pos: [4, 7, 7], state: "ae2:fluix_block"},
        {pos: [5, 7, 7], state: "ae2:fluix_block"},
        {pos: [6, 7, 7], state: "ae2:fluix_block"},
        {pos: [4, 7, 8], state: "ae2:quartz_block"},
        {pos: [4, 8, 0], state: "ae2:quartz_block"},
        {pos: [2, 8, 1], state: "ae2:fluix_block"},
        {pos: [3, 8, 1], state: "ae2:fluix_block"},
        {pos: [4, 8, 1], state: "ae2:fluix_block"},
        {pos: [5, 8, 1], state: "ae2:fluix_block"},
        {pos: [6, 8, 1], state: "ae2:fluix_block"},
        {pos: [1, 8, 2], state: "ae2:fluix_block"},
        {pos: [2, 8, 2], state: "ae2:fluix_block"},
        {pos: [6, 8, 2], state: "ae2:fluix_block"},
        {pos: [7, 8, 2], state: "ae2:fluix_block"},
        {pos: [1, 8, 3], state: "ae2:fluix_block"},
        {pos: [3, 8, 3], state: "ufo:stellar_field_generator_t1"},
        {pos: [5, 8, 3], state: "ufo:stellar_field_generator_t1"},
        {pos: [7, 8, 3], state: "ae2:fluix_block"},
        {pos: [0, 8, 4], state: "ae2:quartz_block"},
        {pos: [1, 8, 4], state: "ae2:fluix_block"},
        {pos: [4, 8, 4], state: "ufo:stellar_field_generator_t1"},
        {pos: [7, 8, 4], state: "ae2:fluix_block"},
        {pos: [8, 8, 4], state: "ae2:quartz_block"},
        {pos: [1, 8, 5], state: "ae2:fluix_block"},
        {pos: [3, 8, 5], state: "ufo:stellar_field_generator_t1"},
        {pos: [5, 8, 5], state: "ufo:stellar_field_generator_t1"},
        {pos: [7, 8, 5], state: "ae2:fluix_block"},
        {pos: [1, 8, 6], state: "ae2:fluix_block"},
        {pos: [2, 8, 6], state: "ae2:fluix_block"},
        {pos: [6, 8, 6], state: "ae2:fluix_block"},
        {pos: [7, 8, 6], state: "ae2:fluix_block"},
        {pos: [2, 8, 7], state: "ae2:fluix_block"},
        {pos: [3, 8, 7], state: "ae2:fluix_block"},
        {pos: [4, 8, 7], state: "ae2:fluix_block"},
        {pos: [5, 8, 7], state: "ae2:fluix_block"},
        {pos: [6, 8, 7], state: "ae2:fluix_block"},
        {pos: [4, 8, 8], state: "ae2:quartz_block"},
        {pos: [2, 9, 0], state: "ae2:quartz_block"},
        {pos: [3, 9, 0], state: "ae2:quartz_block"},
        {pos: [4, 9, 0], state: "ae2:quartz_block"},
        {pos: [5, 9, 0], state: "ae2:quartz_block"},
        {pos: [6, 9, 0], state: "ae2:quartz_block"},
        {pos: [1, 9, 1], state: "ae2:quartz_block"},
        {pos: [2, 9, 1], state: "ae2:fluix_block"},
        {pos: [3, 9, 1], state: "ae2:fluix_block"},
        {pos: [4, 9, 1], state: "ae2:fluix_block"},
        {pos: [5, 9, 1], state: "ae2:fluix_block"},
        {pos: [6, 9, 1], state: "ae2:fluix_block"},
        {pos: [7, 9, 1], state: "ae2:quartz_block"},
        {pos: [0, 9, 2], state: "ae2:quartz_block"},
        {pos: [1, 9, 2], state: "ae2:fluix_block"},
        {pos: [2, 9, 2], state: "ae2:fluix_block"},
        {pos: [6, 9, 2], state: "ae2:fluix_block"},
        {pos: [7, 9, 2], state: "ae2:fluix_block"},
        {pos: [8, 9, 2], state: "ae2:quartz_block"},
        {pos: [0, 9, 3], state: "ae2:quartz_block"},
        {pos: [1, 9, 3], state: "ae2:fluix_block"},
        {pos: [3, 9, 3], state: "ufo:stellar_field_generator_t1"},
        {pos: [5, 9, 3], state: "ufo:stellar_field_generator_t1"},
        {pos: [7, 9, 3], state: "ae2:fluix_block"},
        {pos: [8, 9, 3], state: "ae2:quartz_block"},
        {pos: [0, 9, 4], state: "ae2:quartz_block"},
        {pos: [1, 9, 4], state: "ae2:fluix_block"},
        {pos: [4, 9, 4], state: "ufo:stellar_field_generator_t1"},
        {pos: [7, 9, 4], state: "ae2:fluix_block"},
        {pos: [8, 9, 4], state: "ae2:quartz_block"},
        {pos: [0, 9, 5], state: "ae2:quartz_block"},
        {pos: [1, 9, 5], state: "ae2:fluix_block"},
        {pos: [3, 9, 5], state: "ufo:stellar_field_generator_t1"},
        {pos: [5, 9, 5], state: "ufo:stellar_field_generator_t1"},
        {pos: [7, 9, 5], state: "ae2:fluix_block"},
        {pos: [8, 9, 5], state: "ae2:quartz_block"},
        {pos: [0, 9, 6], state: "ae2:quartz_block"},
        {pos: [1, 9, 6], state: "ae2:fluix_block"},
        {pos: [2, 9, 6], state: "ae2:fluix_block"},
        {pos: [6, 9, 6], state: "ae2:fluix_block"},
        {pos: [7, 9, 6], state: "ae2:fluix_block"},
        {pos: [8, 9, 6], state: "ae2:quartz_block"},
        {pos: [1, 9, 7], state: "ae2:quartz_block"},
        {pos: [2, 9, 7], state: "ae2:fluix_block"},
        {pos: [3, 9, 7], state: "ae2:fluix_block"},
        {pos: [4, 9, 7], state: "ae2:fluix_block"},
        {pos: [5, 9, 7], state: "ae2:fluix_block"},
        {pos: [6, 9, 7], state: "ae2:fluix_block"},
        {pos: [7, 9, 7], state: "ae2:quartz_block"},
        {pos: [2, 9, 8], state: "ae2:quartz_block"},
        {pos: [3, 9, 8], state: "ae2:quartz_block"},
        {pos: [4, 9, 8], state: "ae2:quartz_block"},
        {pos: [5, 9, 8], state: "ae2:quartz_block"},
        {pos: [6, 9, 8], state: "ae2:quartz_block"},
        {pos: [2, 10, 1], state: "ufo:quantum_hyper_mechanical_casing"},
        {pos: [3, 10, 1], state: "ufo:quantum_hyper_mechanical_casing"},
        {pos: [4, 10, 1], state: "ufo:quantum_hyper_mechanical_casing"},
        {pos: [5, 10, 1], state: "ufo:quantum_hyper_mechanical_casing"},
        {pos: [6, 10, 1], state: "ufo:quantum_hyper_mechanical_casing"},
        {pos: [1, 10, 2], state: "ufo:quantum_hyper_mechanical_casing"},
        {pos: [2, 10, 2], state: "ufo:quantum_hyper_mechanical_casing"},
        {pos: [3, 10, 2], state: "ufo:quantum_hyper_mechanical_casing"},
        {pos: [4, 10, 2], state: "ufo:quantum_hyper_mechanical_casing"},
        {pos: [5, 10, 2], state: "ufo:quantum_hyper_mechanical_casing"},
        {pos: [6, 10, 2], state: "ufo:quantum_hyper_mechanical_casing"},
        {pos: [7, 10, 2], state: "ufo:quantum_hyper_mechanical_casing"},
        {pos: [1, 10, 3], state: "ufo:quantum_hyper_mechanical_casing"},
        {pos: [2, 10, 3], state: "ufo:quantum_hyper_mechanical_casing"},
        {pos: [3, 10, 3], state: "ufo:quantum_hyper_mechanical_casing"},
        {pos: [4, 10, 3], state: "ufo:quantum_hyper_mechanical_casing"},
        {pos: [5, 10, 3], state: "ufo:quantum_hyper_mechanical_casing"},
        {pos: [6, 10, 3], state: "ufo:quantum_hyper_mechanical_casing"},
        {pos: [7, 10, 3], state: "ufo:quantum_hyper_mechanical_casing"},
        {pos: [1, 10, 4], state: "ufo:quantum_hyper_mechanical_casing"},
        {pos: [2, 10, 4], state: "ufo:quantum_hyper_mechanical_casing"},
        {pos: [3, 10, 4], state: "ufo:quantum_hyper_mechanical_casing"},
        {pos: [4, 10, 4], state: "ufo:quantum_hyper_mechanical_casing"},
        {pos: [5, 10, 4], state: "ufo:quantum_hyper_mechanical_casing"},
        {pos: [6, 10, 4], state: "ufo:quantum_hyper_mechanical_casing"},
        {pos: [7, 10, 4], state: "ufo:quantum_hyper_mechanical_casing"},
        {pos: [1, 10, 5], state: "ufo:quantum_hyper_mechanical_casing"},
        {pos: [2, 10, 5], state: "ufo:quantum_hyper_mechanical_casing"},
        {pos: [3, 10, 5], state: "ufo:quantum_hyper_mechanical_casing"},
        {pos: [4, 10, 5], state: "ufo:quantum_hyper_mechanical_casing"},
        {pos: [5, 10, 5], state: "ufo:quantum_hyper_mechanical_casing"},
        {pos: [6, 10, 5], state: "ufo:quantum_hyper_mechanical_casing"},
        {pos: [7, 10, 5], state: "ufo:quantum_hyper_mechanical_casing"},
        {pos: [1, 10, 6], state: "ufo:quantum_hyper_mechanical_casing"},
        {pos: [2, 10, 6], state: "ufo:quantum_hyper_mechanical_casing"},
        {pos: [3, 10, 6], state: "ufo:quantum_hyper_mechanical_casing"},
        {pos: [4, 10, 6], state: "ufo:quantum_hyper_mechanical_casing"},
        {pos: [5, 10, 6], state: "ufo:quantum_hyper_mechanical_casing"},
        {pos: [6, 10, 6], state: "ufo:quantum_hyper_mechanical_casing"},
        {pos: [7, 10, 6], state: "ufo:quantum_hyper_mechanical_casing"},
        {pos: [2, 10, 7], state: "ufo:quantum_hyper_mechanical_casing"},
        {pos: [3, 10, 7], state: "ufo:quantum_hyper_mechanical_casing"},
        {pos: [4, 10, 7], state: "ufo:quantum_hyper_mechanical_casing"},
        {pos: [5, 10, 7], state: "ufo:quantum_hyper_mechanical_casing"},
        {pos: [6, 10, 7], state: "ufo:quantum_hyper_mechanical_casing"},
        {pos: [3, 11, 2], state: "ufo:quantum_hyper_mechanical_casing"},
        {pos: [4, 11, 2], state: "ufo:quantum_hyper_mechanical_casing"},
        {pos: [5, 11, 2], state: "ufo:quantum_hyper_mechanical_casing"},
        {pos: [2, 11, 3], state: "ufo:quantum_hyper_mechanical_casing"},
        {pos: [3, 11, 3], state: "ufo:quantum_hyper_mechanical_casing"},
        {pos: [4, 11, 3], state: "ufo:quantum_hyper_mechanical_casing"},
        {pos: [5, 11, 3], state: "ufo:quantum_hyper_mechanical_casing"},
        {pos: [6, 11, 3], state: "ufo:quantum_hyper_mechanical_casing"},
        {pos: [2, 11, 4], state: "ufo:quantum_hyper_mechanical_casing"},
        {pos: [3, 11, 4], state: "ufo:quantum_hyper_mechanical_casing"},
        {pos: [4, 11, 4], state: "ufo:quantum_hyper_mechanical_casing"},
        {pos: [5, 11, 4], state: "ufo:quantum_hyper_mechanical_casing"},
        {pos: [6, 11, 4], state: "ufo:quantum_hyper_mechanical_casing"},
        {pos: [2, 11, 5], state: "ufo:quantum_hyper_mechanical_casing"},
        {pos: [3, 11, 5], state: "ufo:quantum_hyper_mechanical_casing"},
        {pos: [4, 11, 5], state: "ufo:quantum_hyper_mechanical_casing"},
        {pos: [5, 11, 5], state: "ufo:quantum_hyper_mechanical_casing"},
        {pos: [6, 11, 5], state: "ufo:quantum_hyper_mechanical_casing"},
        {pos: [3, 11, 6], state: "ufo:quantum_hyper_mechanical_casing"},
        {pos: [4, 11, 6], state: "ufo:quantum_hyper_mechanical_casing"},
        {pos: [5, 11, 6], state: "ufo:quantum_hyper_mechanical_casing"},
        {pos: [4, 12, 3], state: "ae2:quartz_block"},
        {pos: [3, 12, 4], state: "ae2:quartz_block"},
        {pos: [4, 12, 4], state: "ae2:quartz_block"},
        {pos: [5, 12, 4], state: "ae2:quartz_block"},
        {pos: [4, 12, 5], state: "ae2:quartz_block"},
        {pos: [4, 13, 4], state: "ae2:quartz_block"}
    ],
    entities: [],
    palette: [
        "ufo:quantum_hyper_mechanical_casing",
        "ufo:me_massive_fluid_hatch",
        "ufo:ae_energy_input_hatch",
        "ufo:quantum_cryoforge_controller",
        "minecraft:blue_ice",
        "ufo:stellar_field_generator_t1",
        "ae2:quartz_vibrant_glass",
        "ae2:quartz_block",
        "ae2:fluix_block"
    ]
}
